Workbook

Sheet DICIEMBRE
B1: PILU | G1: EMPLEADO | H1: HORAS TRABAJADAS | I1: HORAS EXTRAS | J1: NO REMUNERATIVO | K1: AGUINALDO | L1: VACACIONES | M1: ADELANTO | N1: DEPOSITO | O1: EFVO | P1: TOTALES
B2: DETALLE | C2: HS TRABAJADAS | D2: VALOR / HORA | E2: IMPORTE | G2: PILU | H2: =+E3 -> 28059 | I2: =+E4 -> 0 | J2: =+E7 -> 8000 | K2: =+E5 -> 14029.5 | L2: =+E6 -> 15792 | M2: =+E8 -> 20000 | N2: =+E9 -> 38888.07 | O2: =+H2+I2+J2+K2+L2-M2-N2 -> 6992.43 | P2: =+O2+N2+M2 -> 65880.5
B3: SUELDO | C3: 199 | D3: 141 | E3: =C3*D3 -> 28059 | G3: JAVI | H3: =+E14 -> 28059 | I3: =+E15 -> 1269 | J3: =+E18 -> 8000 | K3: =+E16 -> 14029.5 | L3: =+E17 -> 15792 | M3: =+E19 -> 20000 | N3: =+E20 -> 33799.31 | O3: =+H3+I3+J3+K3+L3-M3-N3 -> 13350.19 | P3: =+O3+N3+M3 -> 67149.5
B4: EXTRA | C4: 0 | D4: =+D3*1.5 -> 211.5 | E4: =C4*D4 -> 0 | G4: FACU | H4: =+E25 -> 32238 | I4: =+E26 -> 4860 | J4: =+E29 -> 8000 | K4: =+E27 -> 16119 | L4: =+E28 -> 0 | M4: =+E30 -> 20000 | N4: 0 | O4: =+H4+I4+J4+K4+L4-M4-N4 -> 41217 | P4: =+O4+N4+M4 -> 61217
B5: AGUINALDO | C5: =+E3/2 -> 14029.5 | E5: =+C5 -> 14029.5 | G5: CHACO | H5: =+E35 -> 25870 | I5: =+E36 -> 975 | J5: =+E39 -> 8000 | K5: =+E37 -> 12935 | L5: =+E38 -> 0 | M5: =+E40 -> 20000 | N5: 0 | O5: =+H5+I5+J5+K5+L5-M5-N5 -> 27780 | P5: =+O5+N5+M5 -> 47780
B6: VACACIONES | C6: =+D3*8*14 -> 15792 | E6: =+C6 -> 15792 | G6: JUANI | H6: =+E45 -> 32238 | I6: =+E46 -> 3280.5 | J6: =+E49 -> 8500 | K6: =+E47 -> 16120 | L6: =+E48 -> 0 | M6: =+E50 -> 20000 | N6: =+E51 -> 29219.96 | O6: =+H6+I6+J6+K6+L6-M6-N6 -> 10918.54 | P6: =+O6+N6+M6 -> 60138.5
B7: NO REMUNERATIVO | C7: 8000 | E7: =+C7 -> 8000 | G7: YONA | H7: =+E56 -> 29949.5 | I7: =+E57 -> 0 | J7: =+E60 -> 8000 | K7: =+E58 -> 14974 | L7: =+E59 -> 0 | M7: =+E61 -> 20000 | N7: 0 | O7: =+H7+I7+J7+K7+L7-M7-N7 -> 32923.5 | P7: =+O7+N7+M7 -> 52923.5
B8: ADELANTO | C8: 20000 | E8: =+C8 -> 20000 | G8: MATI | H8: =+E66 -> 21890 | I8: =+E67 -> 990 | J8: =+E70 -> 5000 | K8: =+E68 -> 10945 | L8: =+E69 -> 0 | M8: =+E71 -> 15000 | N8: 0 | O8: =+H8+I8+J8+K8+L8-M8-N8 -> 23825 | P8: =+O8+N8+M8 -> 38825
B9: DEPOSITO | C9: 38888.07 | E9: =+C9 -> 38888.07 | G9: TOTALES | M9: =SUM(M2:M8) -> 135000 | N9: =SUM(N2:N8) -> 101907.34 | O9: =SUM(O2:O8) -> 157006.66 | P9: =+M9+N9+O9 -> 393914
B10: TOTAL A COBRAR | E10: =+E3+E4+E5+E6+E7-E8-E9 -> 6992.43
B12: JAVI
B13: DETALLE | C13: HS TRABAJADAS | D13: VALOR / HORA | E13: IMPORTE
B14: SUELDO | C14: 199 | D14: 141 | E14: =C14*D14 -> 28059
B15: EXTRA | C15: 6 | D15: =+D14*1.5 -> 211.5 | E15: =C15*D15 -> 1269
B16: AGUINALDO | C16: =+E14/2 -> 14029.5 | E16: =+C16 -> 14029.5 | G16: EMPLEADOS | H16: ARCHIVO
B17: VACACIONES | C17: =+D14*8*14 -> 15792 | E17: =+C17 -> 15792
B18: NO REMUNERATIVO | C18: 8000 | E18: =+C18 -> 8000
B19: ADELANTO | C19: 20000 | E19: =+C19 -> 20000 | H19: DEFINIR AREA DE IMPRESIÓN
B20: DEPOSITO | C20: 33799.31 | E20: =+C20 -> 33799.31
B21: TOTAL A COBRAR | E21: =+E14+E15+E16+E17+E18-E19-E20 -> 13350.19
B23: FACU
B24: DETALLE | C24: HS TRABAJADAS | D24: VALOR / HORA | E24: IMPORTE
B25: SUELDO | C25: 199 | D25: 162 | E25: =C25*D25 -> 32238
B26: EXTRA | C26: 20 | D26: =+D25*1.5 -> 243 | E26: =C26*D26 -> 4860
B27: AGUINALDO | C27: =+E25/2 -> 16119 | E27: =+C27 -> 16119
B28: VACACIONES | C28: 0 | E28: =+C28 -> 0
B29: NO REMUNERATIVO | C29: 8000 | E29: =+C29 -> 8000
B30: (ADELANTO) | C30: 20000 | E30: =+C30 -> 20000
B31: TOTAL A COBRAR | E31: =+E25+E26+E27+E28+E29-E30 -> 41217
B33: CHACO
B34: DETALLE | C34: HS TRABAJADAS | D34: VALOR / HORA | E34: IMPORTE
B35: SUELDO | C35: 199 | D35: 130 | E35: =C35*D35 -> 25870
B36: EXTRA | C36: 5 | D36: =+D35*1.5 -> 195 | E36: =C36*D36 -> 975
B37: AGUINALDO | C37: =+E35/2 -> 12935 | E37: =+C37 -> 12935
B38: VACACIONES | C38: 0 | E38: =+C38 -> 0
B39: NO REMUNERATIVO | C39: 8000 | E39: =+C39 -> 8000
B40: ADELANTO | C40: 20000 | E40: =+C40 -> 20000
B41: TOTAL A COBRAR | E41: =+E35+E36+E37+E38+E39-E40 -> 27780
B43: JUANI
B44: DETALLE | C44: HS TRABAJADAS | D44: VALOR / HORA | E44: IMPORTE
...

Sheet ENERO
B1: PILU | G1: EMPLEADO | H1: HS TRABAJADAS | I1: HS EXTRAS | J1: NO REMUN. | K1: AGUINALDO | L1: VACACIONES | M1: TOTALES | N1: ADELANTO | O1: DEPOSITO | P1: EFVO
B2: DETALLE | C2: HS TRABAJADAS | D2: VALOR / HORA | E2: IMPORTE | G2: PILU | H2: =+E3 -> 12452 | I2: =+E4 -> 0 | J2: =+E7 -> 8000 | K2: =+E5 -> 0 | L2: =+E6 -> 0 | M2: =+H2+J2+I2+K2+L2 -> 20452 | N2: =+E8 -> 0 | O2: =+E9 -> 12227.28 | P2: =+H2+I2+J2+K2+L2-N2-O2 -> 8224.72
B3: SUELDO | C3: 88 | D3: 141.5 | E3: =C3*D3 -> 12452 | G3: JAVI | H3: =+E14 -> 12452 | I3: =+E15 -> 636.75 | J3: =+E18 -> 8000 | K3: =+E16 -> 0 | L3: =+E17 -> 0 | M3: =+H3+J3+I3+K3+L3 -> 21088.75 | N3: =+E19 -> 3000 | O3: =+E20 -> 10752.43 | P3: =+H3+I3+J3+K3+L3-N3-O3 -> 7336.32
B4: EXTRA | C4: 0 | D4: =+D3*1.5 -> 212.25 | E4: =C4*D4 -> 0 | G4: FACU | H4: =+E25 -> 27692 | I4: =+E26 -> 1806 | J4: =+E29 -> 8000 | K4: =+E27 -> 0 | L4: =+E28 -> 0 | M4: =+H4+J4+I4+K4+L4 -> 37498 | N4: =+E30 -> 3000 | O4: 0 | P4: =+H4+I4+J4+K4+L4-N4-O4 -> 34498
B5: AGUINALDO | C5: 0 | E5: =+C5 -> 0 | G5: CHACO | H5: =+E35 -> 23920 | I5: =+E36 -> 682.5 | J5: =+E39 -> 8000 | K5: =+E37 -> 0 | L5: =+E38 -> 0 | M5: =+H5+J5+I5+K5+L5 -> 32602.5 | N5: =+E40 -> 3000 | O5: 0 | P5: =+H5+I5+J5+K5+L5-N5-O5 -> 29602.5
B6: VACACIONES | C6: 0 | E6: =+C6 -> 0 | G6: JUANI | H6: =+E45 -> 29808 | I6: =+E46 -> 972 | J6: =+E49 -> 13500 | K6: =+E47 -> 0 | L6: =+E48 -> 18144 | M6: =+H6+J6+I6+K6+L6 -> 62424 | N6: =+E50 -> 33720 | O6: =+E51+E52 -> 22393.59 | P6: =+H6+I6+J6+K6+L6-N6-O6 -> 6310.41
B7: NO REMUNERATIVO | C7: 8000 | E7: =+C7 -> 8000 | G7: YONA | H7: =+E57 -> 27692 | I7: =+E58 -> 3837.75 | J7: =+E61 -> 13000 | K7: =+E59 -> 0 | L7: =+E60 -> 0 | M7: =+H7+J7+I7+K7+L7 -> 44529.75 | N7: 1000 | O7: 0 | P7: =+H7+I7+J7+K7+L7-N7-O7 -> 43529.75
B8: ADELANTO | C8: 0 | E8: =+C8 -> 0 | G8: MATI | H8: =+E67 -> 20240 | I8: =+E68 -> 990 | J8: =+E71 -> 5000 | K8: =+E69 -> 0 | L8: =+E70 -> 0 | M8: =+H8+J8+I8+K8+L8 -> 26230 | N8: =+E72 -> 0 | O8: 0 | P8: =+H8+I8+J8+K8+L8-N8-O8 -> 26230
B9: DEPOSITO | C9: 12227.28 | E9: =+C9 -> 12227.28 | G9: GUILLERMO | H9: =+E77 -> 8690 | I9: =+E78 -> 0 | K9: =+E79 -> 0 | L9: =+E80 -> 0 | M9: =+H9+J9+I9+K9+L9 -> 8690 | N9: =+E82 -> 0 | O9: 0 | P9: =+H9+I9+J9+K9+L9-N9-O9 -> 8690
B10: TOTAL A COBRAR | E10: =+E3+E4+E5+E6+E7-E8-E9 -> 8224.72 | G10: MARTIN | H10: =+E97 -> 33000 | M10: =+H10+J10+I10+K10+L10 -> 33000 | P10: =+H10+I10+J10+K10+L10-N10-O10 -> 33000
G11: SILVI | H11: =+E87 -> 25000 | I11: =+E88+E89 -> 9687.5 | J11: =+E91 -> 0 | K11: 0 | L11: =+E90 -> 0 | M11: =+H11+J11+I11+K11+L11 -> 34687.5 | N11: =+E92 -> 0 | O11: 0 | P11: =+H11+I11+J11+K11+L11-N11-O11 -> 34687.5
B12: JAVI | G12: TOTALES | M12: =SUM(M2:M11) -> 321202.5 | N12: =SUM(N2:N11) -> 43720 | O12: =SUM(O2:O11) -> 45373.3 | P12: =SUM(P2:P11) -> 232109.2
B13: DETALLE | C13: HS TRABAJADAS | D13: VALOR / HORA | E13: IMPORTE | N13: =+N12+O12+P12 -> 321202.5
B14: SUELDO | C14: 88 | D14: 141.5 | E14: =C14*D14 -> 12452
B15: EXTRA | C15: 3 | D15: =+D14*1.5 -> 212.25 | E15: =C15*D15 -> 636.75
B16: AGUINALDO | C16: 0 | E16: =+C16 -> 0
B17: VACACIONES | C17: 0 | E17: =+C17 -> 0
B18: NO REMUNERATIVO | C18: 8000 | E18: =+C18 -> 8000 | K18: HORA | L18: HORA X | M18: SOBRESUELDO | N18: NO REM.
B19: ADELANTO | C19: 3000 | E19: =+C19 -> 3000 | G19: EMPLEADOS | H19: ARCHIVO | J19: JUANI | K19: 162 | L19: 243 | M19: 3500 | N19: 5000
B20: DEPOSITO | C20: 10752.43 | E20: =+C20 -> 10752.43 | J20: JONA | K20: 150.5 | L20: 225.75 | M20: 3000 | N20: 5000
B21: TOTAL A COBRAR | E21: =+E14+E15+E16+E17+E18-E19-E20 -> 7336.32 | J21: FACU | K21: 150.5 | L21: 225.75 | M21: 3000 | N21: 5000
H22: DEFINIR AREA DE IMPRESIÓN | J22: PILU | K22: 141.25 | L22: 211.87 | M22: 3000 | N22: 5000
B23: FACU | J23: JAVI | K23: 141.25 | L23: 211.87 | M23: 3000 | N23: 5000
B24: DETALLE | C24: HS TRABAJADAS | D24: VALOR / HORA | E24: IMPORTE | J24: CHACO | K24: 130 | L24: 195 | M24: 3000 | N24: 5000
B25: SUELDO | C25: 184 | D25: 150.5 | E25: =C25*D25 -> 27692 | J25: GUILLERMO | K25: 110 | L25: 165
B26: EXTRA | C26: 8 | D26: =+D25*1.5 -> 225.75 | E26: =C26*D26 -> 1806 | J26: MATI | K26: 110 | L26: 165 | M26: 0 | N26: 5000
B27: AGUINALDO | C27: 0 | E27: =+C27 -> 0 | I27: 11 dias | J27: MARTIN MOLINA | K27: 3000 X DIA
B28: VACACIONES | C28: 0 | E28: =+C28 -> 0
B29: NO REMUNERATIVO | C29: 8000 | E29: =+C29 -> 8000
B30: ADELANTO | C30: 3000 | E30: =+C30 -> 3000
B31: TOTAL A COBRAR | E31: =+E25+E26+E27+E28+E29-E30 -> 34498 | J31: DETALLE DE GASTOS ENERO
B33: CHACO | J33: GUILLE
B34: DETALLE | C34: HS TRABAJADAS | D34: VALOR / HORA | E34: IMPORTE | K34: epec | L34: 603.6
B35: SUELDO | C35: 184 | D35: 130 | E35: =C35*D35 -> 23920 | K35: cable | L35: 1495
B36: EXTRA | C36: 3.5 | D36: =+D35*1.5 -> 195 | E36: =C36*D36 -> 682.5 | K36: viaticos | L36: 2600
B37: AGUINALDO | C37: 0 | E37: =+C37 -> 0 | J37: 44214 | K37: ADELANTO | M37: 30000
B38: VACACIONES | C38: 0 | E38: =+C38 -> 0 | K38: SEGURO GOL | M38: 900
B39: NO REMUNERATIVO | C39: 8000 | E39: =+C39 -> 8000 | K39: PARABRISA | L39: 10310
B40: ADELANTO | C40: 3000 | E40: =+C40 -> 3000
B41: TOTAL A COBRAR | E41: =+E35+E36+E37+E38+E39-E40 -> 29602.5
...

Sheet FEB
B1: PILU | G1: EMPLEADO | H1: HS TRABAJADAS | I1: HS EXTRAS | J1: NO REMUN. | K1: VACACIONES | L1: TOTALES | M1: ADELANTO | N1: DEPOSITO | O1: EFVO
B2: DETALLE | C2: HS TRABAJADAS | D2: VALOR / HORA | E2: IMPORTE | G2: PILU | H2: =+E3 -> 29440.8 | I2: =+E4 -> 0 | J2: =+E5 -> 8000 | K2: 0 | L2: =+H2+I2+J2+K2 -> 37440.8 | M2: =+E6 -> 0 | N2: =+E7 -> 20152.27 | O2: =+L2-M2-N2 -> 17288.53
B3: SUELDO | C3: 174 | D3: 169.2 | E3: =C3*D3 -> 29440.8 | G3: JAVI | H3: =+E12 -> 29440.8 | I3: =+E13 -> 0 | J3: =+E14 -> 8000 | K3: 0 | L3: =+H3+I3+J3+K3 -> 37440.8 | M3: =+E15 -> 11000 | N3: =+E16 -> 17674.95 | O3: =+L3-M3-N3 -> 8765.85
B4: EXTRA | D4: =+D3*1.5 -> 253.8 | E4: =C4*D4 -> 0 | G4: FACU | H4: =+E21 -> 23400 | I4: =+E22+E25 -> 9370 | J4: =+E24 -> 8000 | K4: =+E23 -> 8428 | L4: =+H4+I4+J4+K4 -> 49198 | M4: =+E27+E26 -> 10428 | N4: 0 | O4: =+L4-M4-N4 -> 38770
B5: NO REMUNERATIVO | C5: 8000 | E5: =+C5 -> 8000 | G5: CHACO | H5: =+E32 -> 16770 | I5: =+E33 -> 780 | J5: =+E36 -> 8000 | K5: =+E35 -> 14560 | L5: =+H5+I5+J5+K5 -> 40110 | M5: =+E37 -> 0 | N5: 0 | O5: =+L5-M5-N5 -> 40110
B6: ADELANTO | E6: =+C6 -> 0 | G6: JUANI | H6: =+E42 -> 33756 | I6: =+E43 -> 727.5 | J6: =+E44 -> 8500 | L6: =+H6+I6+J6+K6 -> 42983.5 | M6: =+E45 -> 18144 | N6: =+E46 -> 20348.89 | O6: =+H6+I6+J6-K6-M6-N6 -> 4490.61
B7: DEPOSITO | E7: 20152.27 | G7: YONA | H7: =+E51 -> 31320 | I7: =+E52 -> 0 | J7: =+E53 -> 8000 | K7: 0 | L7: =+H7+I7+J7+K7 -> 39320 | M7: =+E54 -> 10000 | N7: 0 | O7: =+H7+J7-M7 -> 29320
B8: TOTAL A COBRAR | E8: =+E3+E4+E5-E6-E7 -> 17288.53 | F8: AUMENTO DE HORA 20 % | G8: MATI | H8: =+E60 -> 22968 | I8: =+E61 -> 1782 | J8: =+E62 -> 5000 | K8: 0 | L8: =+H8+I8+J8+K8 -> 29750 | M8: 0 | N8: 0 | O8: =+L8-M8-N8 -> 29750
G9: GUILLERMO | H9: =+E68 -> 19140 | I9: =+E69 -> 0 | J9: 0 | K9: 0 | L9: =K9+H9+I9+J9 -> 19140 | M9: =+E70 -> 0 | N9: 0 | O9: =+L9-M9-N9 -> 19140
B10: JAVI | G10: MARTIN | H10: =+E81 -> 54000 | L10: =K10+H10+I10+J10 -> 54000 | O10: =+L10-M10-N10 -> 54000
B11: DETALLE | C11: HS TRABAJADAS | D11: VALOR / HORA | E11: IMPORTE | G11: SILVI | H11: =+E75 -> 25000 | I11: =+E76 -> 0 | J11: 0 | K11: 0 | L11: =K11+H11+I11+J11 -> 25000 | M11: 0 | N11: 0 | O11: =+L11-M11-N11 -> 25000
B12: SUELDO | C12: 174 | D12: 169.2 | E12: =C12*D12 -> 29440.8 | G12: TOTALES | M12: =SUM(M2:M11) -> 49572 | N12: =SUM(N2:N11) -> 58176.11 | O12: =SUM(O2:O11) -> 266634.99
B13: EXTRA | D13: =+D12*1.5 -> 253.8 | E13: =C13*D13 -> 0 | M13: =+N12+O12+M12 -> 374383.1
B14: NO REMUNERATIVO | C14: 8000 | E14: =+C14 -> 8000
B15: ADELANTO | E15: 11000 | G15: FEBRERO 174 HS
B16: DEPOSITO | E16: 17674.95
B17: TOTAL A COBRAR | E17: =+E12+E13+E14-E15-E16 -> 8765.85
K18: HORA | L18: HORA X | M18: SOBRESUELDO | N18: NO REM.
B19: FACU | G19: EMPLEADOS | H19: ARCHIVO | J19: JUANI | K19: 194 | L19: =+K19*1.5 -> 291 | N19: 8500
B20: DETALLE | C20: HS TRABAJADAS | D20: VALOR / HORA | E20: IMPORTE | J20: JONA | K20: 180 | L20: =+K20*1.5 -> 270 | N20: 8000
B21: SUELDO | C21: 130 | D21: 180 | E21: =C21*D21 -> 23400 | J21: FACU | K21: 180 | L21: =+K21*1.5 -> 270 | N21: 8000
B22: EXTRA | C22: 11 | D22: =+D21*1.5 -> 270 | E22: =C22*D22 -> 2970 | H22: DEFINIR AREA DE IMPRESIÓN | J22: PILU | K22: 169.2 | L22: =+K22*1.5 -> 253.8 | N22: 8000
B23: VACACIONES (Pagado) | C23: 56 | D23: 150.5 | E23: =+C23*D23 -> 8428 | J23: JAVI | K23: 169.2 | L23: =+K23*1.5 -> 253.8 | N23: 8000
B24: NO REMUNERATIVO | C24: 8000 | E24: =+C24 -> 8000 | J24: CHACO | K24: 156 | L24: =+K24*1.5 -> 234 | N24: 8000
B25: viaticos febrero | E25: 6400 | J25: GUILLERMO | K25: 110 | L25: =+K25*1.5 -> 165
B26: VACACIONES 7 DIAS | E26: 8428 | J26: MATI | K26: 132 | L26: =+K26*1.5 -> 198 | M26: 0 | N26: 5000
B27: A CUENTA VIATICOS | E27: 2000 | J27: MARTIN MOLINA | K27: 3000 X DIA
B28: TOTAL A COBRAR | E28: =+E21+E22+E23+E24+E25-E26-E27 -> 38770 | F28: =+E21+E22+E23+E24+E25 -> 49198
B30: CHACO
B31: DETALLE | C31: HS TRABAJADAS | D31: VALOR / HORA | E31: IMPORTE | J31: DETALLE DE GASTOS ENERO / FEBRERO
B32: SUELDO | C32: 129 | D32: 130 | E32: =C32*D32 -> 16770 | G32: =130*1.2 -> 156
B33: EXTRA | C33: 4 | D33: =+D32*1.5 -> 195 | E33: =C33*D33 -> 780 | J33: GUILLE
B34: AGUINALDO | E34: =+C34 -> 0 | F34: =150-C32 -> 21 | G34: =+D32*F34 -> 2730 | K34: epec ENERO | L34: 603.6
B35: VACACIONES | C35: 112 | D35: 130 | E35: =+C35*D35 -> 14560 | K35: cable ENERO | L35: 1495
B36: NO REMUNERATIVO | C36: 8000 | E36: =+C36 -> 8000 | K36: cable FEBRERO | L36: 1495
B37: ADELANTO | E37: =+C37 -> 0 | G37: PAGADO PPIO MES SE DEBE EL 20% | K37: viaticos | L37: 2600
B38: TOTAL A COBRAR | E38: =+E32+E33+E34+E35+E36-E37 -> 40110 | K38: DIF. ADELANTO | L38: -2200
J39: FEBRERO | K39: SEGURO GOL | M39: 903.62
B40: JUANI | J40: FEBRERO | K40: SEGURO CLIO | M40: 903.62
B41: DETALLE | C41: HS TRABAJADAS | D41: VALOR / HORA | E41: IMPORTE | K41: PARABRISA | L41: 10310
...

Sheet MARZO
B2: PILU | I2: MARZO
B3: DETALLE | C3: HS TRABAJADAS | D3: VALOR / HORA | E3: IMPORTE | I3: EMPLEADO | J3: HS TRABAJADAS | K3: HS EXTRAS | L3: NO REMUN. | M3: VACACIONES | N3: TOTALES | O3: ADELANTO | P3: DEPOSITO | Q3: EFVO
B4: SUELDO | C4: 194 | D4: 169.2 | E4: =C4*D4 -> 32824.8 | I4: PILU | J4: =+E4 -> 32824.8 | K4: =+E5 -> 0 | L4: =+E6 -> 8000 | M4: 0 | N4: =+J4+K4+L4+M4 -> 40824.8 | O4: =+E7 -> 0 | P4: =+E8 -> 20348.89 | Q4: =+N4-O4-P4 -> 20475.91
B5: EXTRA | C5: 0 | D5: =+D4*1.5 -> 253.8 | E5: =C5*D5 -> 0 | I5: JAVI | J5: =+E13 -> 32824.8 | K5: =+E14 -> 0 | L5: =+E15 -> 8000 | M5: 0 | N5: =+J5+K5+L5+M5 -> 40824.8 | O5: =+E16 -> 6000 | P5: =+E17 -> 17674.95 | Q5: =+N5-O5-P5 -> 17149.85
B6: NO REMUNERATIVO | C6: 8000 | E6: =+C6 -> 8000 | I6: FACU | J6: =+E22 -> 34920 | K6: =+E23+E26 -> 810 | L6: =+E24 -> 8000 | M6: 0 | N6: =+J6+K6+L6+M6 -> 43730 | O6: 0 | P6: 0 | Q6: =+N6 -> 43730
B7: ADELANTO | E7: 0 | I7: CHACO | J7: =+E31 -> 23400 | K7: =+E32 -> 2709 | L7: =+E34 -> 8000 | M7: 0 | N7: =+J7+K7+L7+M7 -> 34109 | O7: =+E35 -> 7000 | P7: 0 | Q7: =+N7-O7 -> 27109
B8: DEPOSITO | E8: 20348.89 | I8: JUANI | J8: =+E40 -> 37636 | K8: =+E41 -> 2473.5 | L8: =+E42 -> 13500 | N8: =+J8+K8+L8+M8 -> 53609.5 | O8: 0 | P8: =+E43 -> 20348.89 | Q8: =+N8-O8-P8 -> 33260.61
B9: TOTAL A COBRAR | E9: =+E4+E5+E6-E7-E8 -> 20475.91 | I9: JONA | J9: =+E48 -> 34920 | K9: =+E49 -> 0 | L9: =+E50 -> 13000 | M9: 0 | N9: =+J9+K9+L9+M9 -> 47920 | O9: =+E51 -> 13000 | P9: 0 | Q9: =+N9-O9-P9 -> 34920
I10: MATI | J10: =+E56 -> 25608 | K10: =+E57 -> 1089 | L10: =+E58 -> 5000 | M10: 0 | N10: =+J10+K10+L10+M10 -> 31697 | O10: 0 | P10: 0 | Q10: =+N10-O10-P10 -> 31697
B11: JAVI | I11: FABIAN | J11: =+E64 -> 21340 | K11: =+E65 -> 495 | L11: 0 | M11: 0 | N11: =M11+J11+K11+L11 -> 21835 | O11: =+E66 -> 0 | P11: 0 | Q11: =+N11-O11-P11 -> 21835
B12: DETALLE | C12: HS TRABAJADAS | D12: VALOR / HORA | E12: IMPORTE | I12: MARTIN | J12: =+E77 -> 63000 | N12: =M12+J12+K12+L12 -> 63000 | O12: 0 | Q12: =+N12-O12-P12 -> 63000
B13: SUELDO | C13: 194 | D13: 169.2 | E13: =C13*D13 -> 32824.8 | I13: SILVI | J13: =+E71 -> 25000 | K13: =+E72 -> 2343.75 | L13: 0 | M13: 0 | N13: =M13+J13+K13+L13 -> 27343.75 | O13: 0 | P13: 0 | Q13: =+N13-O13-P13 -> 27343.75
B14: EXTRA | C14: 0 | D14: =+D13*1.5 -> 253.8 | E14: =C14*D14 -> 0 | I14: TOTALES | O14: =SUM(O4:O13) -> 26000 | P14: =SUM(P4:P13) -> 58372.73 | Q14: =SUM(Q4:Q13) -> 320521.12
B15: NO REMUNERATIVO | C15: 8000 | E15: =+C15 -> 8000 | O15: =+P14+Q14+O14 -> 404893.85
B16: ADELANTO | E16: 6000
B17: DEPOSITO | E17: 17674.95 | I17: marzo 194 HS
B18: TOTAL A COBRAR | E18: =+E13+E14+E15-E16-E17 -> 17149.85
B20: FACU | M20: HORA | N20: HORA X | O20: SOBRESUELDO | P20: NO REM.
B21: DETALLE | C21: HS TRABAJADAS | D21: VALOR / HORA | E21: IMPORTE | I21: EMPLEADOS | J21: ARCHIVO | L21: JUANI | M21: 194 | N21: =+M21*1.5 -> 291 | P21: 13500
B22: SUELDO | C22: 194 | D22: 180 | E22: =C22*D22 -> 34920 | L22: JONA | M22: 180 | N22: =+M22*1.5 -> 270 | P22: 13000
B23: EXTRA | C23: 3 | D23: =+D22*1.5 -> 270 | E23: =C23*D23 -> 810 | L23: FACU | M23: 180 | N23: =+M23*1.5 -> 270 | P23: 8000
B24: NO REMUNERATIVO | C24: 8000 | E24: =+C24 -> 8000 | J24: DEFINIR AREA DE IMPRESIÓN | L24: PILU | M24: 169.2 | N24: =+M24*1.5 -> 253.8 | P24: 8000
B25: VIATICOS DEL 29/03 AL 01/04 | C25: 4 | D25: 1600 | E25: =+C25*D25 -> 6400 | L25: JAVI | M25: 169.2 | N25: =+M25*1.5 -> 253.8 | P25: 8000
B26: ADELANTO | C26: 0 | E26: 0 | L26: CHACO | M26: 156 | N26: =+M26*1.5 -> 234 | P26: 3000
B27: TOTAL A COBRAR | E27: =+E22+E23+E24+E25 -> 50130 | L27: FABIAN | M27: 110 | N27: =+M27*1.5 -> 165 | P27: 7000
H28: DIAS | I28: HS | L28: MATI | M28: 132 | N28: =+M28*1.5 -> 198 | O28: 0 | P28: 5000
B29: CHACO | F29: PAGADO} SE DEBE EL 20% | H29: 18 | I29: 9 | J29: =+H29*I29 -> 162 | L29: MARTIN MOLINA | M29: 3000 X DIA
B30: DETALLE | C30: HS TRABAJADAS | D30: VALOR / HORA | E30: IMPORTE | H30: 4 | I30: 8 | J30: =+H30*I30 -> 32
B31: SUELDO | C31: 150 | D31: 156 | E31: =C31*D31 -> 23400 | H31: hs mes | J31: =SUM(J29:J30) -> 194
B32: DIFERENCIA AUMENTO FEB | C32: 129 | D32: 21 | E32: =+C32*D32 -> 2709
B33: EXTRA | D33: =+D31*1.5 -> 234 | E33: =C33*D33 -> 0
B34: NO REMUNERATIVO | C34: 8000 | E34: =+C34 -> 8000
B35: ADELANTO | E35: 7000
B36: TOTAL A COBRAR | E36: =+E31+E32+E33+E34-E35 -> 27109
B38: JUANI
B39: DETALLE | C39: HS TRABAJADAS | D39: VALOR / HORA | E39: IMPORTE
B40: SUELDO | C40: 194 | D40: 194 | E40: =C40*D40 -> 37636
B41: EXTRA | C41: 8.5 | D41: =+D40*1.5 -> 291 | E41: =C41*D41 -> 2473.5
B42: NO REMUNERATIVO | C42: 13500 | E42: =+C42 -> 13500 | F42: AUMENTO 5000
B43: DEPOSITO | E43: 20348.89
...

Sheet ABRIL
B1: PILU | G1: EMPLEADO | H1: HS TRABAJADAS | I1: HS EXTRAS | J1: NO REMUN. | K1: VACACIONES | L1: TOTALES | M1: ADELANTO | N1: DEPOSITO | O1: EFVO
B2: DETALLE | C2: HS TRABAJADAS | D2: VALOR / HORA | E2: IMPORTE | G2: PILU | H2: =+E3 -> 32486.4 | I2: =+E4 -> 507.6 | J2: =+E5 -> 8000 | K2: 0 | L2: =+H2+I2+J2+K2 -> 40994 | M2: =+E7 -> 0 | N2: =+E8 -> 25616.57 | O2: =+L2-M2-N2 -> 15377.43
B3: SUELDO | C3: 192 | D3: 169.2 | E3: =C3*D3 -> 32486.4 | G3: JAVI | H3: =+E13 -> 32486.4 | I3: =+E14 -> 0 | J3: =+E15 -> 8000 | K3: 0 | L3: =+H3+I3+J3+K3 -> 40486.4 | M3: =+E17 -> 10000 | N3: =+E18 -> 22240.27 | O3: =+L3-M3-N3 -> 8246.13
B4: EXTRA | C4: 2 | D4: =+D3*1.5 -> 253.8 | E4: =C4*D4 -> 507.6 | G4: FACU | H4: =+E23 -> 34560 | I4: =+E24+E27 -> 810 | J4: =+E25 -> 8000 | K4: 0 | L4: =+H4+I4+J4+K4 -> 43370 | M4: 0 | N4: 0 | O4: =+L4 -> 43370
B5: NO REMUNERATIVO | C5: 8000 | E5: =+C5 -> 8000 | G5: CHACO | H5: =+E32 -> 29952 | I5: =+E33 -> 117 | J5: =+E34 -> 8000 | K5: 0 | L5: =+H5+I5+J5+K5 -> 38069 | M5: =+E36 -> 10000 | N5: 0 | O5: =+L5-M5 -> 28069
B6: TOTAL SUELDO | E6: =+E3+E4+E5 -> 40994 | G6: JUANI | H6: =+E41 -> 37248 | I6: =+E42 -> 1891.5 | J6: =+E43 -> 13500 | L6: =+H6+I6+J6+K6 -> 52639.5 | M6: 0 | N6: =+E45 -> 25616.57 | O6: =+L6-M6-N6 -> 27022.93
B7: ADELANTO | E7: 0 | G7: JONA | H7: =+E50 -> 34560 | I7: =+E51 -> 0 | J7: =+E52 -> 13000 | K7: 0 | L7: =+H7+I7+J7+K7 -> 47560 | M7: =+E54 -> 10000 | N7: 0 | O7: =+L7-M7-N7 -> 37560
B8: DEPOSITO | E8: 25616.57 | G8: MATI | H8: =+E59 -> 25344 | I8: =+E60 -> 891 | J8: =+E61 -> 5000 | K8: 0 | L8: =+H8+I8+J8+K8 -> 31235 | M8: 0 | N8: 0 | O8: =+L8-M8-N8 -> 31235
B9: TOTAL A COBRAR | E9: =+E3+E4+E5-E7-E8 -> 15377.43 | G9: FABIAN | H9: =+E68 -> 21120 | I9: =+E69 -> 165 | J9: 0 | K9: 0 | L9: =K9+H9+I9+J9 -> 21285 | M9: =+E71 -> 0 | N9: 0 | O9: =+L9-M9-N9 -> 21285
G10: SILVI | H10: =+E76 -> 25000 | I10: =+E77 -> 820.3125 | J10: 0 | K10: 0 | L10: =K10+H10+I10+J10 -> 25820.312 | M10: 0 | N10: 0 | O10: =+L10-M10-N10 -> 25820.312
B11: JAVI | G11: TOTALES | M11: =SUM(M2:M10) -> 30000 | N11: =SUM(N2:N10) -> 73473.41 | O11: =SUM(O2:O10) -> 237985.8
B12: DETALLE | C12: HS TRABAJADAS | D12: VALOR / HORA | E12: IMPORTE | M12: =+N11+O11+M11 -> 341459.21
B13: SUELDO | C13: 192 | D13: 169.2 | E13: =C13*D13 -> 32486.4
B14: EXTRA | C14: 0 | D14: =+D13*1.5 -> 253.8 | E14: =C14*D14 -> 0 | G14: FALTA FERIADO DE MARZO
B15: NO REMUNERATIVO | C15: 8000 | E15: =+C15 -> 8000
B16: TOTAL SUELDO | E16: =+E13+E14+E15 -> 40486.4
B17: ADELANTO | E17: 10000 | K17: HORA | L17: HORA X | M17: SOBRESUELDO | N17: NO REM.
B18: DEPOSITO | E18: 22240.27 | G18: EMPLEADOS | H18: ARCHIVO | J18: JUANI | K18: 194 | L18: =+K18*1.5 -> 291 | N18: 13500
B19: TOTAL A COBRAR | E19: =+E13+E14+E15-E17-E18 -> 8246.13 | J19: JONA | K19: 180 | L19: =+K19*1.5 -> 270 | N19: 13000
J20: FACU | K20: 180 | L20: =+K20*1.5 -> 270 | N20: 8000
B21: FACU | H21: DEFINIR AREA DE IMPRESIÓN | J21: PILU | K21: 169.2 | L21: =+K21*1.5 -> 253.8 | N21: 8000
B22: DETALLE | C22: HS TRABAJADAS | D22: VALOR / HORA | E22: IMPORTE | J22: JAVI | K22: 169.2 | L22: =+K22*1.5 -> 253.8 | N22: 8000
B23: SUELDO | C23: 192 | D23: 180 | E23: =C23*D23 -> 34560 | J23: CHACO | K23: 156 | L23: =+K23*1.5 -> 234 | N23: 3000
B24: EXTRA | C24: 3 | D24: =+D23*1.5 -> 270 | E24: =C24*D24 -> 810 | J24: FABIAN | K24: 110 | L24: =+K24*1.5 -> 165 | N24: 7000
B25: NO REMUNERATIVO | C25: 8000 | E25: =+C25 -> 8000 | J25: MATI | K25: 132 | L25: =+K25*1.5 -> 198 | M25: 0 | N25: 5000
B26: TOTAL SUELDO | E26: =+E23+E24+E25 -> 43370
B27: ADELANTO | C27: 0 | E27: 0
B28: TOTAL A COBRAR | E28: =+E23+E24+E25-E27 -> 43370 | H28: DIAS | I28: HS
H29: 16 | I29: 9 | J29: =+H29*I29 -> 144
B30: CHACO | H30: 6 | I30: 8 | J30: =+H30*I30 -> 48
B31: DETALLE | C31: HS TRABAJADAS | D31: VALOR / HORA | E31: IMPORTE | H31: hs mes | J31: =SUM(J29:J30) -> 192
B32: SUELDO | C32: 192 | D32: 156 | E32: =C32*D32 -> 29952
B33: EXTRA | C33: 0.5 | D33: =+D32*1.5 -> 234 | E33: =C33*D33 -> 117
B34: NO REMUNERATIVO | C34: 8000 | E34: =+C34 -> 8000
B35: TOTAL SUELDO | E35: =+E34+E33+E32 -> 38069
B36: ADELANTO | E36: 10000
B37: TOTAL A COBRAR | E37: =+E32+E33+E34-E36 -> 28069
B39: JUANI
B40: DETALLE | C40: HS TRABAJADAS | D40: VALOR / HORA | E40: IMPORTE
B41: SUELDO | C41: 192 | D41: 194 | E41: =C41*D41 -> 37248
...

Sheet MAYO
B1: PILU | G1: EMPLEADO | H1: HS TRABAJADAS | I1: HS EXTRAS | J1: NO REMUN. | K1: VACACIONES | L1: TOTALES | M1: ADELANTO | N1: DEPOSITO | O1: EFVO
B2: DETALLE | C2: HS TRABAJADAS | D2: VALOR / HORA | E2: IMPORTE | G2: PILU | H2: =+E3 -> 32317.2 | I2: =+E4 -> 1015.2 | J2: =+E5 -> 8000 | K2: 0 | L2: =+H2+I2+J2+K2 -> 41332.4 | M2: =+E7 -> 0 | N2: =+E8 -> 25616.57 | O2: =+L2-M2-N2 -> 15715.83
B3: SUELDO | C3: 191 | D3: 169.2 | E3: =C3*D3 -> 32317.2 | G3: JAVI | H3: =+E13 -> 7444.8 | I3: 20000 | J3: =+E16 -> 2000 | K3: =+E17+E18 -> 21589.58 | L3: =+H3+I3+J3+K3 -> 51034.38 | M3: =+E20 -> 0 | N3: =+E21 -> 19199.24 | O3: =+L3-M3-N3 -> 31835.14
B4: EXTRA | C4: 4 | D4: =+D3*1.5 -> 253.8 | E4: =C4*D4 -> 1015.2 | G4: FACU | H4: =+E26 -> 34380 | I4: =+E27+E30 -> 1080 | J4: =+E28 -> 8000 | K4: 0 | L4: =+H4+I4+J4+K4 -> 43460 | M4: 0 | N4: 0 | O4: =+L4 -> 43460
B5: NO REMUNERATIVO | C5: 8000 | E5: =+C5 -> 8000 | G5: CHACO | H5: =+E35 -> 29796 | I5: =+E36 -> 2223 | J5: =+E37 -> 8000 | K5: 0 | L5: =+H5+I5+J5+K5 -> 40019 | M5: =+E39 -> 10000 | N5: 0 | O5: =+L5-M5 -> 30019
B6: TOTAL SUELDO | E6: =+E3+E4+E5 -> 41332.4 | G6: JUANI | H6: =+E44 -> 37054 | I6: =+E45 -> 2764.5 | J6: =+E46 -> 13500 | L6: =+H6+I6+J6+K6 -> 53318.5 | M6: 0 | N6: =+E48 -> 25616.57 | O6: =+L6-M6-N6 -> 27701.93
B7: ADELANTO | E7: 0 | G7: JONA | H7: =+E53 -> 26280 | I7: =+E54 -> 0 | J7: =+E56 -> 13000 | K7: =+E55 -> 10620 | L7: =+H7+I7+J7+K7 -> 49900 | M7: =+E58 -> 10000 | N7: 0 | O7: =+L7-M7-N7 -> 39900
B8: DEPOSITO | E8: 25616.57 | G8: MATI | H8: =+E63 -> 19272 | I8: =+E64 -> 0 | J8: =+E65 -> 7000 | K8: =+E66 -> 7392 | L8: =+H8+I8+J8+K8 -> 33664 | M8: 0 | N8: 0 | O8: =+L8-M8-N8 -> 33664
B9: TOTAL A COBRAR | E9: =+E3+E4+E5-E7-E8 -> 15715.83 | G9: FABIAN | H9: =+E73 -> 21010 | I9: =+E74 -> 660 | J9: =+E75 -> 3000 | K9: 0 | L9: =+H9+I9+J9+K9 -> 24670 | M9: =+E77 -> 0 | N9: 0 | O9: =+L9-M9-N9 -> 24670
G10: SILVI | H10: =+E82 -> 25000 | I10: =+E83 -> 0 | J10: 0 | K10: 0 | L10: =K10+H10+I10+J10 -> 25000 | M10: 0 | N10: 0 | O10: =+L10-M10-N10 -> 25000
B11: JAVI | G11: TOTALES MAYO | M11: =SUM(M2:M10) -> 20000 | N11: =SUM(N2:N10) -> 70432.38 | O11: =SUM(O2:O10) -> 271965.9
B12: DETALLE | C12: HS TRABAJADAS | D12: VALOR / HORA | E12: IMPORTE | M12: =+N11+O11+M11 -> 362398.28
B13: SUELDO | C13: 44 | D13: 169.2 | E13: =C13*D13 -> 7444.8
B14: EXTRA | C14: 0 | D14: =+D13*1.5 -> 253.8 | E14: =C14*D14 -> 0 | G14: FALTA FERIADO DE MARZO
B15: EXTRA | E15: 20000
B16: PROPORC. NO REMUN. | C16: 2000 | E16: =+C16 -> 2000
B17: PROP. VACACIONES | E17: 9964.42
B18: PROPORC. AGUINALDO | E18: 11625.16
B19: TOTAL SUELDO | E19: =+E13+E16+E17+E18+E15 -> 51034.38 | K19: HORA | L19: HORA X | M19: SOBRESUELDO | N19: NO REM.
B20: ADELANTO | E20: 0 | G20: EMPLEADOS | H20: ARCHIVO | J20: JUANI | K20: 194 | L20: =+K20*1.5 -> 291 | N20: 13500
B21: DEPOSITO | E21: 19199.24 | J21: JONA | K21: 180 | L21: =+K21*1.5 -> 270 | N21: 13000
B22: TOTAL A COBRAR | E22: =+E19-E20-E21 -> 31835.14 | J22: FACU | K22: 180 | L22: =+K22*1.5 -> 270 | N22: 8000
H23: DEFINIR AREA DE IMPRESIÓN | J23: PILU | K23: 169.2 | L23: =+K23*1.5 -> 253.8 | N23: 8000
B24: FACU | J24: JAVI | K24: 169.2 | L24: =+K24*1.5 -> 253.8 | N24: 8000
B25: DETALLE | C25: HS TRABAJADAS | D25: VALOR / HORA | E25: IMPORTE | J25: CHACO | K25: 156 | L25: =+K25*1.5 -> 234 | N25: 3000
B26: SUELDO | C26: 191 | D26: 180 | E26: =C26*D26 -> 34380 | J26: FABIAN | K26: 110 | L26: =+K26*1.5 -> 165 | N26: 7000
B27: EXTRA | C27: 4 | D27: =+D26*1.5 -> 270 | E27: =C27*D27 -> 1080 | J27: MATI | K27: 132 | L27: =+K27*1.5 -> 198 | M27: 0 | N27: 5000
B28: NO REMUNERATIVO | C28: 8000 | E28: =+C28 -> 8000
B29: TOTAL SUELDO | E29: =+E26+E27+E28 -> 43460
B30: ADELANTO | C30: 0 | E30: 0
B31: TOTAL A COBRAR | E31: =+E29-E30 -> 43460
G32: DIAS | H32: HS
B33: CHACO | G33: 15 | H33: 9 | I33: =+G33*H33 -> 135
B34: DETALLE | C34: HS TRABAJADAS | D34: VALOR / HORA | E34: IMPORTE | G34: 7 | H34: 8 | I34: =+G34*H34 -> 56
B35: SUELDO | C35: 191 | D35: 156 | E35: =C35*D35 -> 29796 | G35: hs mes | I35: =SUM(I33:I34) -> 191
B36: EXTRA | C36: 9.5 | D36: =+D35*1.5 -> 234 | E36: =C36*D36 -> 2223
B37: NO REMUNERATIVO | C37: 8000 | E37: =+C37 -> 8000
B38: TOTAL SUELDO | E38: =+E37+E36+E35 -> 40019
B39: ADELANTO | E39: 10000
B40: TOTAL A COBRAR | E40: =+E35+E36+E37-E39 -> 30019
...

Sheet JUNIO
B1: PILU | G1: EMPLEADO | H1: HS TRABAJADAS | I1: FERIADOS | J1: HS EXTRAS | K1: NO REMUN. | L1: aguinaldo (mayor mes) | M1: TOTALES | N1: ADELANTO | O1: DEPOSITO | P1: EFVO
B2: DETALLE | C2: HS TRABAJADAS | D2: VALOR / HORA | E2: IMPORTE | G2: PILU | H2: =+E3 -> 31302 | I2: =+E4 -> 1353.6 | J2: =+E5 -> 0 | K2: =+E7 -> 8000 | L2: =+E6 -> 16497 | M2: =SUM(H2:L2) -> 57152.6 | N2: =+E9 -> 0 | O2: =+E10 -> 37221.48 | P2: =+M2-N2-O2 -> 19931.12
B3: SUELDO | C3: 185 | D3: 169.2 | E3: =C3*D3 -> 31302 | G3: FACU | H3: =+E15 -> 33300 | I3: =+E16 -> 1440 | J3: =+E17+E21 -> 1350 | K3: =+E19 -> 8000 | L3: =+E18 -> 18045 | M3: =SUM(H3:L3) -> 62135 | N3: 0 | O3: 0 | P3: =+M3 -> 62135
B4: FERIADO | C4: 8 | D4: 169.2 | E4: =C4*D4 -> 1353.6 | G4: CHACO | H4: =+E26 -> 28860 | I4: =+E27 -> 1248 | J4: =+E28 -> 936 | K4: =+E30 -> 8000 | L4: =+E29 -> 16009.5 | M4: =SUM(H4:L4) -> 55053.5 | N4: =+E32 -> 10000 | O4: 0 | P4: =+M4-N4 -> 45053.5
B5: EXTRA | C5: 0 | D5: =+D3*1.5 -> 253.8 | E5: =C5*D5 -> 0 | G5: JUANI | H5: =+E37 -> 35890 | I5: =+E38 -> 1552 | J5: =+E39 -> 1891.5 | K5: =+E41 -> 13500 | L5: =+E40 -> 20055 | M5: =SUM(H5:L5) -> 72888.5 | N5: 0 | O5: =+E44 -> 0 | P5: =+M5-N5-O5 -> 72888.5
B6: AGUINALDO (base Abril) | E6: =32994/2 -> 16497 | G6: JONA | H6: =+E49 -> 33300 | I6: =+E50 -> 1440 | J6: =+E51 -> 405 | K6: =+E53 -> 13000 | L6: =+E52 -> 17872.5 | M6: =SUM(H6:L6) -> 66017.5 | N6: =+E55 -> 10000 | O6: 0 | P6: =+M6-N6-O6 -> 56017.5
B7: NO REMUNERATIVO | C7: 8000 | E7: =+C7 -> 8000 | G7: MATI | H7: =+E60 -> 24420 | I7: =+E61 -> 1056 | J7: =+E62 -> 1584 | K7: =+E64 -> 7000 | L7: =+E63 -> 13580 | M7: =SUM(H7:L7) -> 47640 | N7: =+E66 -> 0 | O7: 0 | P7: =+M7-N7-O7 -> 47640
B8: TOTAL SUELDO | E8: =SUM(E3:E7) -> 57152.6 | G8: FABIAN | H8: =+E71 -> 20350 | I8: =+E72 -> 880 | J8: =+E73 -> 330 | K8: =+E75 -> 3000 | L8: =+E74 -> 7276.6667 | M8: =SUM(H8:L8) -> 31836.667 | N8: =+E77 -> 4000 | O8: 0 | P8: =+M8-N8-O8 -> 27836.667
B9: ADELANTO | E9: 0 | G9: SILVI | H9: =+E82 -> 25000 | I9: + | J9: =+E84 -> 468.75 | K9: 0 | L9: =+E83 -> 13650 | M9: =SUM(H9:L9) -> 39118.75 | N9: 0 | O9: 0 | P9: =+M9-N9-O9 -> 39118.75
B10: DEPOSITO | E10: 37221.48 | G10: TOTALES JUNIO | N10: =SUM(N2:N9) -> 24000 | O10: =SUM(O2:O9) -> 37221.48 | P10: =SUM(P2:P9) -> 370621.04
B11: TOTAL A COBRAR | E11: =+E8-E10 -> 19931.12 | N11: =+O10+P10+N10 -> 431842.52
G12: DIAS | H12: HS
B13: FACU | F13: LABORAL | G13: 17 | H13: 9 | J13: =+G13*H13 -> 153 | L13: aguinaldo (mayor mes) :194 HS
B14: DETALLE | C14: HS TRABAJADAS | D14: VALOR / HORA | E14: IMPORTE | F14: FERIADO | G14: 1 | H14: 8 | J14: =+G14*H14 -> 8 | L14: sumar hs extras
B15: SUELDO | C15: 185 | D15: 180 | E15: =C15*D15 -> 33300 | F15: VIERNES | G15: 4 | H15: 8 | J15: =+G15*H15 -> 32
B16: FERIADO | C16: 8 | D16: 180 | E16: =C16*D16 -> 1440 | G16: hs mes | J16: =SUM(J13:J15) -> 193
B17: EXTRA | C17: 5 | D17: =+D15*1.5 -> 270 | E17: =C17*D17 -> 1350
B18: AGUINALDO (Base Junio) | E18: =36090/2 -> 18045 | L18: HORA | M18: HORA X | O18: NO REM.
B19: NO REMUNERATIVO | C19: 8000 | E19: =+C19 -> 8000 | K19: JUANI | L19: 194 | M19: =+L19*1.5 -> 291 | O19: 13500
B20: TOTAL SUELDO | E20: =SUM(E15:E19) -> 62135 | G20: EMPLEADOS | H20: ARCHIVO | K20: JONA | L20: 180 | M20: =+L20*1.5 -> 270 | O20: 13000
B21: ADELANTO | C21: 0 | E21: 0 | K21: FACU | L21: 180 | M21: =+L21*1.5 -> 270 | O21: 8000
B22: TOTAL A COBRAR | E22: =+E20-E21 -> 62135 | K22: PILU | L22: 169.2 | M22: =+L22*1.5 -> 253.8 | O22: 8000
H23: DEFINIR AREA DE IMPRESIÓN | K23: CHACO | L23: 156 | M23: =+L23*1.5 -> 234 | O23: 8000
B24: CHACO | K24: FABIAN | L24: 110 | M24: =+L24*1.5 -> 165 | O24: 3000
B25: DETALLE | C25: HS TRABAJADAS | D25: VALOR / HORA | E25: IMPORTE | K25: MATI | L25: 132 | M25: =+L25*1.5 -> 198 | O25: 7000
B26: SUELDO | C26: 185 | D26: 156 | E26: =C26*D26 -> 28860
B27: FERIADO | C27: 8 | D27: 156 | E27: =C27*D27 -> 1248
B28: EXTRA | C28: 4 | D28: =+D26*1.5 -> 234 | E28: =C28*D28 -> 936
B29: AGUINALDO (Base Mayo) | E29: 16009.5
B30: NO REMUNERATIVO | C30: 8000 | E30: =+C30 -> 8000
B31: TOTAL SUELDO | E31: =SUM(E26:E30) -> 55053.5
B32: ADELANTO | E32: 10000
B33: TOTAL A COBRAR | E33: =+E31-E32 -> 45053.5
B35: JUANI
B36: DETALLE | C36: HS TRABAJADAS | D36: VALOR / HORA | E36: IMPORTE
B37: SUELDO | C37: 185 | D37: 194 | E37: =C37*D37 -> 35890
B38: FERIADO | C38: 8 | D38: 194 | E38: =C38*D38 -> 1552
B39: EXTRA | C39: 6.5 | D39: =+D37*1.5 -> 291 | E39: =C39*D39 -> 1891.5
B40: AGUINALDO (Base Marzo) | E40: =40110/2 -> 20055
B41: NO REMUNERATIVO | C41: 13500 | E41: =+C41 -> 13500
...

Sheet JULIO
B1: PILU | H1: EMPLEADO | I1: HS TRABAJADAS | J1: FERIADOS | K1: HS EXTRAS | L1: NO REMUN. | M1: TOTALES | N1: ADELANTO | O1: DEPOSITO | P1: EFVO
B2: DETALLE | C2: HS TRABAJADAS | D2: VALOR / HORA | E2: IMPORTE | H2: PILU | I2: =+E3 -> 31302 | J2: =+E5 -> 1353.6 | K2: =+E6+E7+E4 -> 3634.5 | L2: =+E8 -> 8000 | M2: =SUM(I2:L2) -> 44290.1 | N2: =+E10 -> 0 | O2: =+E11 -> 25616.57 | P2: =+M2-N2-O2 -> 18673.53
B3: SUELDO | C3: 185 | D3: 169.2 | E3: =C3*D3 -> 31302 | H3: FACU | I3: =+E16 -> 33300 | J3: =+E18 -> 1440 | K3: =+E20+E19+E17 -> 5655 | L3: =+E21 -> 8000 | M3: =SUM(I3:L3) -> 48395 | N3: 0 | O3: 0 | P3: =+M3 -> 48395
B4: EXTRA POR VIAJE | E4: 3000 | H4: CHACO | I4: =+E28 -> 28860 | J4: =+E30 -> 1248 | K4: =+E31+E32+E29 -> 3585 | L4: =+E33 -> 8000 | M4: =SUM(I4:L4) -> 41693 | N4: =+E35 -> 10000 | O4: 0 | P4: =+M4-N4 -> 31693
B5: FERIADO | C5: 8 | D5: 169.2 | E5: =C5*D5 -> 1353.6 | H5: JUANI | I5: =+E40 -> 35890 | J5: =+E41 -> 1552 | K5: =+E43+E42 -> 3152.5 | L5: =+E44 -> 13500 | M5: =SUM(I5:L5) -> 54094.5 | N5: 0 | O5: =+E47 -> 25616.57 | P5: =+M5-N5-O5 -> 28477.93
B6: EXTRA | C6: 2.5 | D6: =+D3*1.5 -> 253.8 | E6: =C6*D6 -> 634.5 | H6: JONA | I6: =+E52+E56+E57+E58 -> 31500 | J6: =+E53 -> 1440 | K6: =+E54+E55 -> 2385 | L6: =+E59 -> 13000 | M6: =SUM(I6:L6) -> 48325 | N6: =+E61 -> 6000 | O6: 0 | P6: =+M6-N6-O6 -> 42325
B7: EXTRA AL 100% | C7: 0 | D7: =+D5*2 -> 338.4 | E7: =+C7*D7 -> 0 | H7: MATI | I7: =+E66+E68 -> 23100 | J7: =+E67 -> 1056 | K7: =+E69+E70 -> 1650 | L7: =+E71 -> 12000 | M7: =SUM(I7:L7) -> 37806 | N7: =+E73 -> 0 | O7: 0 | P7: =+M7-N7-O7 -> 37806
B8: NO REMUNERATIVO | C8: 8000 | E8: =+C8 -> 8000 | H8: FABIAN | I8: =+E78 -> 4840 | J8: 0 | K8: =+E79 -> 160 | L8: 0 | M8: =SUM(I8:L8) -> 5000 | N8: =+E81 -> 0 | O8: 0 | P8: =+M8-N8-O8 -> 5000
B9: TOTAL SUELDO | E9: =SUM(E3:E8) -> 44290.1 | H9: SILVI | I9: =+E86 -> 25000 | J9: 0 | K9: =+E87 -> 3281.25 | L9: 0 | M9: =SUM(I9:L9) -> 28281.25 | N9: 0 | O9: 0 | P9: =+M9-N9-O9 -> 28281.25
B10: ADELANTO | E10: 0 | H10: TOTALES JULIO | N10: =SUM(N2:N9) -> 16000 | O10: =SUM(O2:O9) -> 51233.14 | P10: =SUM(P2:P9) -> 240651.71
B11: DEPOSITO | E11: 25616.57 | N11: =+O10+P10+N10 -> 307884.85
B12: TOTAL A COBRAR | E12: =+E9-E11 -> 18673.53 | H12: DIAS | I12: HS | J12: JULIO
G13: LABORAL | H13: 17 | I13: 9 | J13: =+H13*I13 -> 153
B14: FACU | G14: FERIADO | H14: 1 | I14: 8 | J14: =+H14*I14 -> 8
B15: DETALLE | C15: HS TRABAJADAS | D15: VALOR / HORA | E15: IMPORTE | G15: VIERNES | H15: 4 | I15: 8 | J15: =+H15*I15 -> 32
B16: SUELDO | C16: 185 | D16: 180 | E16: =C16*D16 -> 33300 | H16: hs mes | J16: =SUM(J13:J15) -> 193
B17: EXTRA POR VIAJE | E17: 3000
B18: FERIADO | C18: 8 | D18: 180 | E18: =C18*D18 -> 1440 | M18: HORA | N18: HORA X | O18: NO REM.
B19: EXTRA AL 100% | C19: 1 | D19: =+D16*2 -> 360 | E19: =C19*D19 -> 360 | L19: JUANI | M19: 194 | N19: =+M19*1.5 -> 291 | O19: 13500
B20: EXTRA | C20: 8.5 | D20: =+D16*1.5 -> 270 | E20: =C20*D20 -> 2295 | H20: EMPLEADOS | I20: ARCHIVO | L20: JONA | M20: 180 | N20: =+M20*1.5 -> 270 | O20: 13000
B21: NO REMUNERATIVO | C21: 8000 | E21: =+C21 -> 8000 | L21: FACU | M21: 180 | N21: =+M21*1.5 -> 270 | O21: 8000
B22: TOTAL SUELDO | E22: =SUM(E16:E21) -> 48395 | L22: PILU | M22: 169.2 | N22: =+M22*1.5 -> 253.8 | O22: 8000
B23: ADELANTO | E23: 0 | I23: DEFINIR AREA DE IMPRESIÓN | L23: CHACO | M23: 156 | N23: =+M23*1.5 -> 234 | O23: 8000
B24: TOTAL A COBRAR | E24: =+E22-E23 -> 48395 | L24: FABIAN | M24: 110 | N24: =+M24*1.5 -> 165 | O24: 3000
L25: MATI | M25: 132 | N25: =+M25*1.5 -> 198 | O25: 12000
B26: CHACO
B27: DETALLE | C27: HS TRABAJADAS | D27: VALOR / HORA | E27: IMPORTE
B28: SUELDO | C28: 185 | D28: 156 | E28: =C28*D28 -> 28860
B29: EXTRA POR VIAJE | E29: 3000
B30: FERIADO | C30: 8 | D30: 156 | E30: =C30*D30 -> 1248 | G30: RAFAELA
B31: EXTRA AL 100% | C31: 0 | D31: =+D28*2 -> 312 | E31: =C31*D31 -> 0 | G31: 44390 | H31: 6,30 A 17 HS | I31: 1.5
B32: EXTRA | C32: 2.5 | D32: =+D28*1.5 -> 234 | E32: =C32*D32 -> 585 | G32: 44391 | H32: 9 A 18 HS | I32: 0
B33: NO REMUNERATIVO | C33: 8000 | E33: =+C33 -> 8000 | G33: 44396 | H33: 7 a 17 hs | I33: 1
B34: TOTAL SUELDO | E34: =SUM(E28:E33) -> 41693 | G34: 44397 | H34: 8,30 a 17,30 hs | I34: 0
B35: ADELANTO | E35: 10000 | G35: 44398 | H35: 8,00 a 17,30 hs | I35: 0
B36: TOTAL A COBRAR | E36: =+E34-E35 -> 31693 | G36: hs. Extras | I36: 2.5
B38: JUANI | G38: plasticos san fco | H38: 6 hs | I38: 1 h. al 100%
B39: DETALLE | C39: HS TRABAJADAS | D39: VALOR / HORA | E39: IMPORTE | G39: juani/jona/facu/mati
B40: SUELDO | C40: 185 | D40: 194 | E40: =C40*D40 -> 35890
B41: FERIADO | C41: 8 | D41: 194 | E41: =C41*D41 -> 1552
...

Sheet AGOSTO
B1: PILU | H1: EMPLEADO | I1: HS TRABAJADAS | J1: FERIADOS | K1: HS EXTRAS | L1: NO REMUN. | M1: TOTALES | N1: ADELANTO | O1: DEPOSITO | P1: EFVO
B2: DETALLE | C2: HS TRABAJADAS | D2: VALOR / HORA | E2: IMPORTE | H2: PILU | I2: =+E3 -> 35735.04 | J2: =+E5 -> 3248.64 | K2: =+E6+E7+E4 -> 761.4 | L2: =+E8 -> 8000 | M2: =SUM(I2:L2) -> 47745.08 | N2: =+E10 -> 0 | O2: =+E11 -> 26672.78 | P2: =+M2-N2-O2 -> 21072.3
B3: SUELDO | C3: 176 | D3: 203.04 | E3: =C3*D3 -> 35735.04 | H3: FACU | I3: =+E16 -> 40972.8 | J3: =+E18 -> 3724.8 | K3: =+E20+E19+E17 -> 3666.6 | L3: =+E21 -> 13000 | M3: =SUM(I3:L3) -> 61364.2 | N3: =+E23 -> 10000 | O3: 0 | P3: =+M3-N3-O3 -> 51364.2
B4: EXTRA POR VIAJE | C4: 0 | H4: CHACO | I4: =+E28 -> 32947.2 | J4: =+E30 -> 2496 | K4: =+E31+E32+E29 -> 3229.2 | L4: =+E33 -> 8000 | M4: =SUM(I4:L4) -> 46672.4 | N4: =+E35 -> 10000 | O4: 0 | P4: =+M4-N4-O4 -> 36672.4
B5: FERIADO | C5: 16 | D5: 203.04 | E5: =C5*D5 -> 3248.64 | H5: JUANI | I5: =+E40 -> 40972.8 | J5: =+E41 -> 3724.8 | K5: =+E43+E42 -> 2793.6 | L5: =+E44 -> 13500 | M5: =SUM(I5:L5) -> 60991.2 | N5: =+E46 -> 0 | O5: =+E47 -> 26672.78 | P5: =+M5-N5-O5 -> 34318.42
B6: EXTRA | C6: 2.5 | D6: =+D3*1.5 -> 304.56 | E6: =C6*D6 -> 761.4 | H6: JONA | I6: =+E52+E54 -> 38016 | J6: =+E53 -> 3456 | K6: =+E55+E56 -> 1458 | L6: =+E57 -> 13000 | M6: =SUM(I6:L6) -> 55930 | N6: =+E59 -> 10000 | O6: 0 | P6: =+M6-N6-O6 -> 45930
B7: EXTRA AL 100% | C7: 0 | D7: =+D5*2 -> 406.08 | E7: =+C7*D7 -> 0 | H7: MATI | I7: =+E64+E66 -> 27720 | J7: =+E65 -> 2534.4 | K7: =+E67+E68 -> 2257.2 | L7: =+E69 -> 8000 | M7: =SUM(I7:L7) -> 40511.6 | N7: =+E71 -> 0 | O7: 0 | P7: =+M7-N7-O7 -> 40511.6
B8: NO REMUNERATIVO | C8: 8000 | E8: =+C8 -> 8000 | H8: SILVI | I8: =+E77 -> 30000 | J8: 0 | K8: =+E78 -> 3375 | L8: 0 | M8: =SUM(I8:L8) -> 33375 | N8: 0 | O8: 0 | P8: =+M8-N8-O8 -> 33375
B9: TOTAL SUELDO | E9: =SUM(E3:E8) -> 47745.08 | H9: TOTALES JULIO | N9: =SUM(N2:N8) -> 30000 | O9: =SUM(O2:O8) -> 53345.56 | P9: =SUM(P2:P8) -> 263243.92
B10: ADELANTO | E10: 0 | N10: =+O9+P9+N9 -> 346589.48
B11: DEPOSITO | E11: 26672.78
B12: TOTAL A COBRAR | E12: =+E9-E11 -> 21072.3 | M12: HORA | N12: HORA X | O12: NO REM.
L13: JUANI | M13: =194*1.2 -> 232.8 | N13: =+M13*1.5 -> 349.2 | O13: 13500
B14: FACU | H14: DIAS | I14: HS | J14: JULIO | L14: JONA | M14: =180*1.2 -> 216 | N14: =+M14*1.5 -> 324 | O14: 13000
B15: DETALLE | C15: HS TRABAJADAS | D15: VALOR / HORA | E15: IMPORTE | G15: LABORAL | H15: 16 | I15: 9 | J15: =+H15*I15 -> 144 | L15: FACU | M15: =180*1.2 -> 216 | N15: =+M15*1.5 -> 324 | O15: 13000
B16: SUELDO | C16: 176 | D16: 232.8 | E16: =C16*D16 -> 40972.8 | G16: FERIADO | H16: 2 | I16: 8 | J16: =+H16*I16 -> 16 | L16: PILU | M16: =169.2*1.2 -> 203.04 | N16: =+M16*1.5 -> 304.56 | O16: 8000
B17: EXTRA POR VIAJE | C17: 0 | E17: 0 | G17: VIERNES | H17: 4 | I17: 8 | J17: =+H17*I17 -> 32 | L17: CHACO | M17: =156*1.2 -> 187.2 | N17: =+M17*1.5 -> 280.8 | O17: 8000
B18: FERIADO | C18: 16 | D18: 232.8 | E18: =C18*D18 -> 3724.8 | H18: hs mes | J18: =SUM(J15:J17) -> 192 | L18: MATI | M18: =132*1.2 -> 158.4 | N18: =+M18*1.5 -> 237.6 | O18: 8000
B19: EXTRA AL 100% | C19: 0 | D19: =+D16*2 -> 465.6 | E19: =C19*D19 -> 0
B20: EXTRA | C20: 10.5 | D20: =+D16*1.5 -> 349.2 | E20: =C20*D20 -> 3666.6 | F20: faltaban declarar 9 Hs | I20: RAFAELA (extras)
B21: NO REMUNERATIVO | C21: 13000 | E21: =+C21 -> 13000 | F21: =9*D20 -> 3142.8 | I21: Chaco, Pilu, Mati
B22: TOTAL SUELDO | E22: =SUM(E16:E21) -> 61364.2 | I22: 44419 | J22: 3
B23: ADELANTO | E23: 10000 | I23: 44425 | J23: 2
B24: TOTAL A COBRAR | E24: =+E22-E23 -> 51364.2 | I24: 44426 | J24: 1.5
I25: 44439 | J25: 1 | K25: chaco y pilu
B26: CHACO | I26: hs. Extras
B27: DETALLE | C27: HS TRABAJADAS | D27: VALOR / HORA | E27: IMPORTE
B28: SUELDO | C28: 176 | D28: 187.2 | E28: =C28*D28 -> 32947.2 | G28: SABADO | H28: 5
B29: EXTRA POR VIAJE | C29: 0 | E29: 0 | G29: CHACO
B30: FERIADO | C30: 16 | D30: 156 | E30: =C30*D30 -> 2496
B31: EXTRA AL 100% | C31: 0 | D31: =+D28*2 -> 374.4 | E31: =C31*D31 -> 0
B32: EXTRA | C32: 11.5 | D32: =+D28*1.5 -> 280.8 | E32: =C32*D32 -> 3229.2
B33: NO REMUNERATIVO | C33: 8000 | E33: =+C33 -> 8000
B34: TOTAL SUELDO | E34: =SUM(E28:E33) -> 46672.4
B35: ADELANTO | E35: 10000
B36: TOTAL A COBRAR | E36: =+E34-E35 -> 36672.4
B38: JUANI
B39: DETALLE | C39: HS TRABAJADAS | D39: VALOR / HORA | E39: IMPORTE
B40: SUELDO | C40: 176 | D40: 232.8 | E40: =C40*D40 -> 40972.8
B41: FERIADO | C41: 16 | D41: 232.8 | E41: =C41*D41 -> 3724.8
...

Sheet SEPT
B1: PILU | H1: EMPLEADO | I1: HS TRABAJADAS | J1: FERIADOS | K1: HS EXTRAS | L1: NO REMUN. | M1: TOTALES | N1: ADELANTO | O1: DEPOSITO | P1: EFVO
B2: DETALLE | C2: HS TRABAJADAS | D2: VALOR / HORA | E2: IMPORTE | H2: PILU | I2: =+E3 -> 39389.76 | J2: =+E5 -> 0 | K2: =+E6+E7+E4 -> 304.56 | L2: =+E8 -> 8000 | M2: =SUM(I2:L2) -> 47694.32 | N2: =+E10 -> 0 | O2: =+E11 -> 28979.54 | P2: =+M2-N2-O2 -> 18714.78
B3: SUELDO | C3: 194 | D3: 203.04 | E3: =C3*D3 -> 39389.76 | H3: FACU | I3: =+E16 -> 45163.2 | J3: =+E18 -> 0 | K3: =+E21+E20+E17 -> 0 | L3: =+E22 -> 13000 | M3: =SUM(I3:L3) -> 58163.2 | N3: =+E24 -> 0 | O3: 0 | P3: =+M3-N3-O3 -> 58163.2
B4: EXTRA POR VIAJE | C4: 0 | H4: CHACO | I4: =+E29 -> 36316.8 | J4: =+E31 -> 0 | K4: =+E32+E33+E30 -> 0 | L4: =+E34 -> 8000 | M4: =SUM(I4:L4) -> 44316.8 | N4: =+E36 -> 10000 | O4: 0 | P4: =+M4-N4-O4 -> 34316.8
B5: FERIADO | C5: 0 | D5: 203.04 | E5: =C5*D5 -> 0 | H5: JUANI | I5: =+E41 -> 45163.2 | J5: =+E42 -> 0 | K5: =+E44+E43 -> 1746 | L5: =+E45 -> 13500 | M5: =SUM(I5:L5) -> 60409.2 | N5: =+E47 -> 0 | O5: =+E48 -> 29538.76 | P5: =+M5-N5-O5 -> 30870.44
B6: EXTRA | C6: 1 | D6: =+D3*1.5 -> 304.56 | E6: =C6*D6 -> 304.56 | H6: JONA | I6: =+E53 -> 41904 | J6: =+E54 -> 0 | K6: =+E55+E56 -> 0 | L6: =+E57 -> 13000 | M6: =SUM(I6:L6) -> 54904 | N6: =+E59 -> 12000 | O6: 0 | P6: =+M6-N6-O6 -> 42904
B7: EXTRA AL 100% | C7: 0 | D7: =+D5*2 -> 406.08 | E7: =+C7*D7 -> 0 | H7: MATI | I7: =+E64 -> 30729.6 | J7: =+E65 -> 0 | K7: =+E66+E67 -> 0 | L7: =+E68 -> 8000 | M7: =SUM(I7:L7) -> 38729.6 | N7: =+E70 -> 0 | O7: 0 | P7: =+M7-N7-O7 -> 38729.6
B8: NO REMUNERATIVO | C8: 8000 | E8: =+C8 -> 8000 | H8: LUCAS | I8: =+E83 -> 27720 | J8: =+E84 -> 0 | K8: =+E85 -> 0 | L8: =+E87 -> 8000 | M8: =SUM(I8:L8) -> 35720 | N8: =+E89 -> 8000 | O8: 0 | P8: =+M8-N8 -> 27720
B9: TOTAL SUELDO | E9: =SUM(E3:E8) -> 47694.32 | H9: SILVI | I9: =+E76 -> 30000 | J9: 0 | K9: =+E77 -> 4050 | L9: 0 | M9: =SUM(I9:L9) -> 34050 | N9: 0 | O9: 0 | P9: =+M9-N9-O9 -> 34050
B10: ADELANTO | E10: 0 | H10: TOTALES JULIO | N10: =SUM(N2:N9) -> 30000 | O10: =SUM(O2:O9) -> 58518.3 | P10: =SUM(P2:P9) -> 285468.82
B11: DEPOSITO | E11: 28979.54 | N11: =+O10+P10+N10 -> 373987.12
B12: TOTAL A COBRAR | E12: =+E9-E11 -> 18714.78
M13: HORA | N13: HORA X | O13: NO REM.
B14: FACU | L14: JUANI | M14: =194*1.2 -> 232.8 | N14: =+M14*1.5 -> 349.2 | O14: 13500
B15: DETALLE | C15: HS TRABAJADAS | D15: VALOR / HORA | E15: IMPORTE | H15: DIAS | I15: HS | J15: SEPT | L15: JONA | M15: =180*1.2 -> 216 | N15: =+M15*1.5 -> 324 | O15: 13000
B16: SUELDO | C16: 194 | D16: 232.8 | E16: =C16*D16 -> 45163.2 | G16: LABORAL | H16: 18 | I16: 9 | J16: =+H16*I16 -> 162 | L16: FACU | M16: =180*1.2 -> 216 | N16: =+M16*1.5 -> 324 | O16: 13000
B17: EXTRA POR VIAJE | C17: 0 | E17: 0 | F17: 08/09/21 RETIRO 11,30 | G17: FERIADO | H17: 0 | I17: 8 | J17: =+H17*I17 -> 0 | L17: PILU | M17: =169.2*1.2 -> 203.04 | N17: =+M17*1.5 -> 304.56 | O17: 8000
B18: FERIADO | C18: 0 | D18: 232.8 | E18: =C18*D18 -> 0 | G18: VIERNES | H18: 4 | I18: 8 | J18: =+H18*I18 -> 32 | L18: CHACO | M18: =156*1.2 -> 187.2 | N18: =+M18*1.5 -> 280.8 | O18: 8000
B19: HORAS EXTRAS AGOSTO | C19: 9 | D19: =+D21 -> 349.2 | E19: =C19*D19 -> 3142.8 | H19: hs mes | J19: =SUM(J16:J18) -> 194 | L19: LUCAS | M19: 165 | N19: =+M19*1.5 -> 247.5 | O19: 8000
B20: EXTRA AL 100% | C20: 0 | D20: =+D16*2 -> 465.6 | E20: =C20*D20 -> 0 | F20: faltaban declarar 9 Hs | L20: MATI | M20: =132*1.2 -> 158.4 | N20: =+M20*1.5 -> 237.6 | O20: 8000
B21: EXTRA | C21: 0 | D21: =+D16*1.5 -> 349.2 | E21: =C21*D21 -> 0 | F21: =9*D21 -> 3142.8
B22: NO REMUNERATIVO | C22: 13000 | E22: =+C22 -> 13000
B23: TOTAL SUELDO | E23: =SUM(E16:E22) -> 61306
B24: ADELANTO | E24: 0
B25: TOTAL A COBRAR | E25: =+E23-E24 -> 61306
B27: CHACO
B28: DETALLE | C28: HS TRABAJADAS | D28: VALOR / HORA | E28: IMPORTE
B29: SUELDO | C29: 194 | D29: 187.2 | E29: =C29*D29 -> 36316.8
B30: EXTRA POR VIAJE | C30: 0 | E30: 0
B31: FERIADO | C31: 0 | D31: 156 | E31: =C31*D31 -> 0
B32: EXTRA AL 100% | C32: 0 | D32: =+D29*2 -> 374.4 | E32: =C32*D32 -> 0
B33: EXTRA | C33: 0 | D33: =+D29*1.5 -> 280.8 | E33: =C33*D33 -> 0
B34: NO REMUNERATIVO | C34: 8000 | E34: =+C34 -> 8000
B35: TOTAL SUELDO | E35: =SUM(E29:E34) -> 44316.8
B36: ADELANTO | E36: 10000
B37: TOTAL A COBRAR | E37: =+E35-E36 -> 34316.8
B39: JUANI
B40: DETALLE | C40: HS TRABAJADAS | D40: VALOR / HORA | E40: IMPORTE
B41: SUELDO | C41: 194 | D41: 232.8 | E41: =C41*D41 -> 45163.2
B42: FERIADO | C42: 0 | D42: 232.8 | E42: =C42*D42 -> 0
...

Sheet OCTUBRE
B1: PILU | H1: EMPLEADO | I1: HS TRABAJADAS | J1: FERIADOS | K1: VACACIONES | L1: HS EXTRAS | M1: NO REMUN. | N1: TOTALES | O1: ADELANTO | P1: DEPOSITO | Q1: EFVO
B2: DETALLE | C2: HS TRABAJADAS | D2: VALOR / HORA | E2: IMPORTE | H2: PILU | I2: =+E3 -> 32080.32 | J2: =+E6 -> 4872.96 | L2: =+E7+E8+E5+E4 -> 3609.12 | M2: =+E9 -> 8000 | N2: =SUM(I2:M2) -> 48562.4 | O2: =+E11 -> 0 | P2: =+E12 -> 29425.38 | Q2: =+N2-O2-P2 -> 19137.02
B3: SUELDO | C3: 158 | D3: 203.04 | E3: =C3*D3 -> 32080.32 | H3: FACU | I3: =+E19+E22 -> 32592 | J3: =+E21 -> 5587.2 | K3: =+E20 -> 13036.8 | L3: =+E23+E24 -> 1629.6 | M3: =+E25 -> 13000 | N3: =SUM(I3:M3) -> 65845.6 | O3: =+E27 -> 5000 | P3: 0 | Q3: =+N3-O3-P3 -> 60845.6
B4: PREMIO | D4: 3000 | E4: 3000 | H4: CHACO | I4: =+E32 -> 29577.6 | J4: =+E34 -> 3744 | L4: =+E35+E36+E33 -> 421.2 | M4: =+E37 -> 8000 | N4: =SUM(I4:M4) -> 41742.8 | O4: =+E39 -> 10000 | P4: 0 | Q4: =+N4-O4-P4 -> 31742.8
B5: EXTRA POR VIAJE | C5: 0 | D5: 0 | H5: JUANI | I5: =+E44 -> 36782.4 | J5: =+E45 -> 5587.2 | L5: =+E48+E47+E46 -> 7550.2 | M5: =+E49 -> 13500 | N5: =SUM(I5:M5) -> 63419.8 | O5: 0 | P5: =+E52 -> 30064.45 | Q5: =+N5-O5-P5 -> 33355.35
B6: FERIADO | C6: 24 | D6: 203.04 | E6: =C6*D6 -> 4872.96 | H6: JONA | I6: =+E57 -> 34128 | J6: =+E59 -> 5184 | K6: =+E58 -> 3456 | L6: =+E60+E61 -> 2160 | M6: =+E62 -> 13000 | N6: =SUM(I6:M6) -> 57928 | O6: =+E65 -> 6000 | P6: =+E64 -> 11023.23 | Q6: =+N6-O6-P6 -> 40904.77
B7: EXTRA | C7: 2 | D7: =+D3*1.5 -> 304.56 | E7: =C7*D7 -> 609.12 | H7: MATI | I7: =+E70 -> 25027.2 | J7: =+E71 -> 3801.6 | L7: =+E72+E73 -> 0 | M7: =+E74 -> 8000 | N7: =SUM(I7:M7) -> 36828.8 | O7: =+E76 -> 0 | P7: 0 | Q7: =+N7-O7-P7 -> 36828.8
B8: EXTRA AL 100% | C8: 0 | D8: =+D6*2 -> 406.08 | E8: =+C8*D8 -> 0 | H8: LUCA | I8: =+E90 -> 26070 | J8: =+E91 -> 3960 | L8: =+E92 -> 0 | M8: =+E94 -> 8000 | N8: =SUM(I8:M8) -> 38030 | O8: =+E96 -> 5000 | P8: 0 | Q8: =+N8-O8 -> 33030
B9: NO REMUNERATIVO | C9: 8000 | E9: =+C9 -> 8000 | H9: SILVI | I9: =+E82 -> 30000 | L9: =+E83+E84 -> 3375 | M9: 0 | N9: =SUM(I9:M9) -> 33375 | O9: 0 | P9: 0 | Q9: =+N9-O9-P9 -> 33375
B10: TOTAL SUELDO | E10: =SUM(E3:E9) -> 48562.4 | H10: TOTALES JULIO | O10: =SUM(O2:O9) -> 26000 | P10: =SUM(P2:P9) -> 70513.06 | Q10: =SUM(Q2:Q9) -> 289219.34
B11: ADELANTO | E11: 0 | O11: =+P10+Q10+O10 -> 385732.4
B12: DEPOSITO | E12: 29425.38
B13: TOTAL A COBRAR | E13: =+E10-E12 -> 19137.02 | N13: HORA | O13: HORA X | P13: NO REM.
M14: JUANI | N14: =194*1.2 -> 232.8 | O14: =+N14*1.5 -> 349.2 | P14: 13500
H15: DIAS | I15: HS | J15: SEPT | M15: JONA | N15: =180*1.2 -> 216 | O15: =+N15*1.5 -> 324 | P15: 13000
G16: LABORAL | H16: 14 | I16: 9 | J16: =+H16*I16 -> 126 | M16: FACU | N16: =180*1.2 -> 216 | O16: =+N16*1.5 -> 324 | P16: 13000
B17: FACU | G17: FERIADO | H17: 3 | I17: 8 | J17: =+H17*I17 -> 24 | M17: PILU | N17: =169.2*1.2 -> 203.04 | O17: =+N17*1.5 -> 304.56 | P17: 8000
B18: DETALLE | C18: HS TRABAJADAS | D18: VALOR / HORA | E18: IMPORTE | G18: VIERNES | H18: 4 | I18: 8 | J18: =+H18*I18 -> 32 | M18: CHACO | N18: =156*1.2 -> 187.2 | O18: =+N18*1.5 -> 280.8 | P18: 8000
B19: SUELDO | C19: 158 | D19: 232.8 | E19: =C19*D19 -> 36782.4 | H19: hs mes | J19: =SUM(J16:J18) -> 182 | M19: LUCA | N19: 165 | O19: =+N19*1.5 -> 247.5 | P19: 8000
B20: VACACIONES 2020 (7 D) | C20: 56 | D20: =+D19 -> 232.8 | E20: =C20*D20 -> 13036.8 | F20: se toma 07/10 y 12/10 | M20: MATI | N20: =132*1.2 -> 158.4 | O20: =+N20*1.5 -> 237.6 | P20: 8000
B21: FERIADO | C21: 24 | D21: 232.8 | E21: =C21*D21 -> 5587.2 | F21: ver vacaciones
B22: LICENCIA X VIAJE | C22: -18 | D22: 232.8 | E22: =C22*D22 -> -4190.4 | F22: SE DEBIAN 5 DIAS
B23: EXTRA AL 100% | C23: 3.5 | D23: =+D19*2 -> 465.6 | E23: =C23*D23 -> 1629.6
B24: EXTRA | C24: 0 | D24: =+D19*1.5 -> 349.2 | E24: =C24*D24 -> 0
B25: NO REMUNERATIVO | C25: 13000 | E25: =+C25 -> 13000
B26: TOTAL SUELDO | E26: =SUM(E19:E25) -> 65845.6
B27: ADELANTO | E27: 5000
B28: TOTAL A COBRAR | E28: =+E26-E27 -> 60845.6
B30: CHACO
B31: DETALLE | C31: HS TRABAJADAS | D31: VALOR / HORA | E31: IMPORTE
B32: SUELDO | C32: 158 | D32: 187.2 | E32: =C32*D32 -> 29577.6
B33: EXTRA POR VIAJE | C33: 0 | E33: 0
B34: FERIADO | C34: 24 | D34: 156 | E34: =C34*D34 -> 3744
B35: EXTRA AL 100% | C35: 0 | D35: =+D32*2 -> 374.4 | E35: =C35*D35 -> 0
B36: EXTRA | C36: 1.5 | D36: =+D32*1.5 -> 280.8 | E36: =C36*D36 -> 421.2
B37: NO REMUNERATIVO | C37: 8000 | E37: =+C37 -> 8000
B38: TOTAL SUELDO | E38: =SUM(E32:E37) -> 41742.8
B39: ADELANTO | E39: 10000
B40: TOTAL A COBRAR | E40: =+E38-E39 -> 31742.8
B42: JUANI
...

Sheet NOVIEMBRE
H1: NOVIEMBRE
B2: PILU | H2: EMPLEADO | I2: HS TRABAJADAS | J2: FERIADOS | K2: LICENCIA | L2: PRESENTISMO | M2: VARIOS | N2: HS EXTRAS | O2: NO REMUN. | P2: TOTALES | Q2: ADELANTO | R2: DEPOSITO | S2: EFVO
B3: DETALLE | C3: HS TRABAJADAS | D3: VALOR / HORA | E3: IMPORTE | H3: PILU | I3: =+E4 -> 37562.4 | J3: =+E7 -> 4872.96 | K3: =+E5 -> 0 | L3: =+E6 -> 5000 | M3: 0 | N3: =+E8+E9 -> 1218.24 | O3: =+E10 -> 11000 | P3: =SUM(I3:O3) -> 59653.6 | Q3: =+E12 -> 0 | R3: =+E13 -> 29425.38 | S3: =+P3-Q3-R3 -> 30228.22
B4: SUELDO | C4: 185 | D4: 203.04 | E4: =C4*D4 -> 37562.4 | H4: FACU | I4: =+E18 -> 43068 | J4: =+E20 -> 2793.6 | K4: =+E19 -> 0 | L4: =+E21 -> 5000 | M4: -990 | N4: =+E22+E23 -> 9195.6 | O4: =+E24 -> 16500 | P4: =SUM(I4:O4) -> 75567.2 | Q4: =+E27 -> 10000 | R4: 0 | S4: =+P4-Q4-R4 -> 65567.2
B5: FALTA/RETIRO | H5: CHACO | I5: =+E32 -> 33134.4 | J5: =+E36 -> 2246.4 | K5: =+E33 -> 1497.6 | L5: =+E35 -> 5000 | M5: 0 | N5: =+E37+E38 -> 5616 | O5: =+E39 -> 11000 | P5: =SUM(I5:O5) -> 58494.4 | Q5: =+E41 -> 10000 | R5: 0 | S5: =+P5-Q5-R5 -> 48494.4
B6: Presentismo | C6: 5000 | D6: 0 | E6: =+C6 -> 5000 | H6: JUANI | I6: =+E46 -> 38877.6 | J6: =+E48 -> 2793.6 | K6: =+E47 -> 13036.8 | L6: =+E49 -> 5000 | M6: 0 | N6: =+E52+E51+E50 -> 8089.8 | O6: =+E53 -> 16500 | P6: =SUM(I6:O6) -> 84297.8 | Q6: 0 | R6: =+E56 -> 30064.45 | S6: =+P6-Q6-R6 -> 54233.35
B7: FERIADO | C7: 12 | D7: =+D4*2 -> 406.08 | E7: =C7*D7 -> 4872.96 | H7: JONA | I7: =+E61 -> 36504 | J7: =+E65 -> 2592 | K7: =+E63+E64 -> 1728 | L7: =+E62 -> 0 | M7: 0 | N7: =+E66+E67 -> 0 | O7: =+E68 -> 16000 | P7: =SUM(I7:O7) -> 56824 | Q7: =+E71 -> 10000 | R7: =+E70 -> 24028.31 | S7: =+P7-Q7-R7 -> 22795.69
B8: EXTRA x 50% | C8: 4 | D8: =+D4*1.5 -> 304.56 | E8: =C8*D8 -> 1218.24 | H8: MATI | I8: =+E76 -> 29304 | J8: =+E77 -> 1900.8 | K8: =+E79 -> -4276.8 | L8: =+E78 -> 0 | M8: 0 | N8: =+E80+E81 -> 5385.6 | O8: =+E82 -> 11000 | P8: =SUM(I8:O8) -> 43313.6 | Q8: =+E84 -> 0 | R8: 0 | S8: =+P8-Q8-R8 -> 43313.6
B9: EXTRA AL 100% | C9: 0 | D9: =+D7*2 -> 812.16 | E9: =+C9*D9 -> 0 | H9: LUCA | I9: =+E96 -> 32214 | J9: =+E97 -> 2184 | K9: =+E99 -> 1456 | L9: =+E98 -> 5000 | M9: 0 | N9: =+E100+E101 -> 6870.5 | O9: =+E102 -> 11000 | P9: =SUM(I9:O9) -> 58724.5 | Q9: =+E104 -> 8000 | R9: 0 | S9: =+P9-Q9 -> 50724.5
B10: NO REMUNERATIVO | C10: 11000 | E10: =+C10 -> 11000 | H10: SILVI | I10: =+E89 -> 30000 | M10: 0 | N10: =+E90+E91 -> 11500 | O10: 0 | P10: =SUM(I10:O10) -> 41500 | Q10: 0 | R10: 0 | S10: =+P10-Q10-R10 -> 41500
B11: TOTAL SUELDO | E11: =SUM(E4:E10) -> 59653.6 | H11: ALEJO | I11: =+E109 -> 16005 | J11: =+E110 -> 1980 | K11: =+E111 -> -1650 | L11: 0 | N11: =+E112+E113 -> 247.5 | O11: =+E114 -> 8000 | P11: =SUM(I11:O11) -> 24582.5 | Q11: 0 | R11: 0 | S11: =+P11-Q11-R11 -> 24582.5
B12: ADELANTO | E12: 0 | H12: TOTALES NOVIEMBRE | Q12: =SUM(Q3:Q10) -> 38000 | R12: =SUM(R3:R10) -> 83518.14 | S12: =SUM(S3:S10) -> 356856.96
B13: DEPOSITO 03/11/21 | E13: 29425.38 | Q13: =+R12+S12+Q12 -> 478375.1
B14: TOTAL A COBRAR | E14: =+E11-E13 -> 30228.22 | L14: =+I4+L4+M4+N4+O4 -> 72773.6
B16: FACU | L16: =+O4+N4+M4+L4+K4+J4+I4 -> 75567.2 | Q16: HORA | R16: HORA X | S16: NO REM.
B17: DETALLE | C17: HS TRABAJADAS | D17: VALOR / HORA | E17: IMPORTE | P17: JUANI | Q17: =194*1.2 -> 232.8 | R17: =+Q17*1.5 -> 349.2 | S17: 13500
B18: SUELDO | C18: 185 | D18: 232.8 | E18: =C18*D18 -> 43068 | I18: DIAS | J18: HS | K18: NOV | P18: JONA | Q18: =180*1.2 -> 216 | R18: =+Q18*1.5 -> 324 | S18: 13000
B19: FALTA/RETIRO | E19: 0 | H19: LABORAL | I19: 17 | J19: 9 | K19: =+I19*J19 -> 153 | P19: FACU | Q19: =180*1.2 -> 216 | R19: =+Q19*1.5 -> 324 | S19: 13500
B20: FERIADO | C20: 12 | D20: 232.8 | E20: =C20*D20 -> 2793.6 | F20: PAGO FERIADO $1862,40 | H20: FERIADO | I20: 1.5 | J20: 8 | K20: =+I20*J20 -> 12 | P20: PILU | Q20: =169.2*1.2 -> 203.04 | R20: =+Q20*1.5 -> 304.56 | S20: 11000
B21: Presentismo | C21: 5000 | E21: 5000 | F21: =4*349 -> 1396 | H21: VIERNES | I21: 4 | J21: 8 | K21: =+I21*J21 -> 32 | P21: CHACO | Q21: =156*1.2 -> 187.2 | R21: =+Q21*1.5 -> 280.8 | S21: 11000
B22: EXTRA AL 100% feriado | C22: 13 | D22: =+D18*2 -> 465.6 | E22: =C22*D22 -> 6052.8 | I22: hs mes | K22: =SUM(K19:K21) -> 197 | P22: LUCA | Q22: 165 | R22: =+Q22*1.5 -> 247.5 | S22: 8000
B23: EXTRA al 50% | C23: 9 | D23: =+D18*1.5 -> 349.2 | E23: =C23*D23 -> 3142.8 | P23: ALEJO | Q23: =132*1.2 -> 158.4 | R23: =+Q23*1.5 -> 237.6 | S23: 8000
B24: NO REMUNERATIVO | C24: 16500 | E24: =+C24 -> 16500 | R24: =+Q24*1.5 -> 0
B25: TOTAL SUELDO | E25: =SUM(E18:E24) -> 76557.2
B26: SEGURO CLIO | E26: 990
B27: ADELANTO | E27: 10000
B28: TOTAL A COBRAR | E28: =+E25-E26-E27 -> 65567.2
B30: CHACO
B31: DETALLE | C31: HS TRABAJADAS | D31: VALOR / HORA | E31: IMPORTE
B32: SUELDO | C32: 177 | D32: 187.2 | E32: =C32*D32 -> 33134.4 | F32: =185-8 -> 177
B33: LICENCIA X ENFERMEDAD | C33: 8 | D33: 187.2 | E33: =+C33*D33 -> 1497.6
B34: FALTA/RETIRO | D34: -187.2 | E34: =+C34*D34 -> 0
B35: Presentismo | C35: 5000 | E35: 5000
B36: FERIADO no trabajado | C36: 12 | D36: =+D32 -> 187.2 | E36: =+C36*D36 -> 2246.4
B37: Feriado EXTRA AL 100% | C37: 9 | D37: =+D32*2 -> 374.4 | E37: =C37*D37 -> 3369.6
B38: EXTRA al 50% | C38: 8 | D38: =+D32*1.5 -> 280.8 | E38: =C38*D38 -> 2246.4
B39: NO REMUNERATIVO | C39: 11000 | E39: =+C39 -> 11000
B40: TOTAL SUELDO | E40: =SUM(E32:E39) -> 58494.4
B41: ADELANTO | E41: 10000
B42: TOTAL A COBRAR | E42: =+E40-E41 -> 48494.4
...

Sheet DICIEMBRE21
B2: PILU | H2: DICIEMBRE
B3: DETALLE | C3: HS TRABAJADAS | D3: VALOR / HORA | E3: IMPORTE | H3: EMPLEADO | I3: HS TRABAJADAS | J3: FERIADOS | K3: LICENCIA | L3: PRESENTISMO | M3: aguinaldo | N3: HS EXTRAS | O3: NO REMUN. | P3: vs | Q3: TOTALES | R3: ADELANTO | S3: DEPOSITO | T3: EFVO
B4: SUELDO | C4: 181 | D4: 203.04 | E4: =C4*D4 -> 36750.24 | H4: PILU | I4: =+E4 -> 36750.24 | J4: =+E5 -> 2436.48 | K4: =+E6 -> 22740.48 | L4: =+E9 -> 5000 | M4: =+E7 -> 29825 | N4: =+E12+E11 -> 2284.2 | O4: =+E13 -> 11000 | Q4: =SUM(I4:O4) -> 110036.4 | R4: =+E15 -> 29825 | S4: =+E16 -> 30000 | T4: =+Q4-R4-S4 -> 50211.4
B5: FERIADO | C5: 12 | D5: =+D4 -> 203.04 | E5: =+C5*D5 -> 2436.48 | H5: =+++++++++++++F3 -> 0 | I5: =+E21 -> 42136.8 | J5: =+E22 -> 2793.6 | L5: =+E26 -> 5000 | M5: =+E24 -> 38250 | N5: =+E29+E28 -> 3317.4 | O5: =+E30 -> 16500 | P5: =+E33 -> 990 | Q5: =SUM(I5:P5) -> 108987.8 | R5: =+E36 -> 38250 | T5: =+Q5-R5 -> 70737.8
B6: VACACIONES | C6: =14*8 -> 112 | D6: =+D5 -> 203.04 | E6: =+C6*D6 -> 22740.48 | H6: CHACO | I6: =+E41 -> 33883.2 | J6: =+E42 -> 2246.4 | K6: =+E43 -> 20966.4 | L6: =+E46 -> 5000 | M6: =+E44 -> 29250 | N6: =+E48+E49 -> 982.8 | O6: =+E50 -> 11000 | Q6: =SUM(I6:O6) -> 103328.8 | R6: =+E52 -> 29250 | S6: =+E53 -> 20966.4 | T6: =+Q6-R6-S6 -> 53112.4
B7: AGUINALDO (Base: Dic.) | E7: 29825 | H7: JUANI | I7: =+E58 -> 36084 | J7: =+E59 -> 2793.6 | K7: =+E60 -> 0 | L7: =+E63 -> 5000 | M7: =+E61 -> 40300 | N7: =+E66+E65 -> 2793.6 | O7: =+E67 -> 16500 | Q7: =SUM(I7:O7) -> 103471.2 | R7: =+E69 -> 40300 | S7: =+E70 -> 24313.15 | T7: =+Q7-R7-S7 -> 38858.05
B8: FALTA/RETIRO sin justif | D8: =-D4 -> -203.04 | E8: =+C8*D8 -> 0 | H8: JONA | I8: =+E75 -> 15120 | J8: =+E76 -> 2592 | K8: =+E81 -> 21384 | L8: =+E80 -> 0 | M8: =+E78 -> 24800 | N8: =+E83+E82 -> 0 | O8: =+E84 -> 16000 | Q8: =SUM(I8:O8) -> 79896 | R8: =+E87 -> 28400 | S8: =+E86 -> 24028.31 | T8: =+Q8-R8-S8 -> 27467.69
B9: Presentismo | C9: 5000 | E9: =+C9 -> 5000 | H9: LUCA | I9: =+E101 -> 32942 | J9: =+E102 -> 2184 | L9: =+E106 -> 5000 | M9: =+E104 -> 18300 | N9: =+E109+E108 -> 2184 | O9: =+E110 -> 11000 | Q9: =SUM(I9:O9) -> 71610 | R9: =+E112 -> 18300 | T9: =+Q9-R9 -> 53310
B10: LICENCIA ENFERMEDAD | E10: =C10*D10 -> 0 | H10: SILVI | I10: =+E92 -> 30000 | L10: =+E93 -> 3600 | M10: =+E96 -> 21000 | O10: 0 | P10: =+E94 -> 8590.9091 | Q10: =SUM(I10:P10) -> 63190.909 | R10: =+E96 -> 21000 | T10: =+Q10-R10-S10 -> 42190.909
B11: HORA EXTRA x 50% | C11: 7.5 | D11: =+D4*1.5 -> 304.56 | E11: =C11*D11 -> 2284.2 | H11: LUIS | I11: =+E140 -> 25575 | J11: =+E141 -> 1980 | L11: =+E145 -> 5000 | M11: =+E143 -> 4000 | N11: =+E109+E108 -> 2184 | O11: =+E149 -> 8000 | Q11: =SUM(I11:O11) -> 46739 | R11: =+E151 -> 4000 | T11: =+Q11-R11-S11 -> 42739
B12: HORA EXTRA AL 100% | D12: =+D10*2 -> 0 | E12: =+C12*D12 -> 0 | H12: ALEJO | I12: =+E119 -> 29865 | J12: =+E120 -> 1980 | K12: =+E123+E124 -> 0 | L12: =+E125 -> 0 | M12: =+E122 -> 6000 | N12: =+E128+E127 -> 866.25 | O12: =+E129 -> 8000 | Q12: =SUM(I12:O12) -> 46711.25 | R12: =+E131 -> 6000 | T12: =+Q12-R12-S12 -> 40711.25
B13: NO REMUNERATIVO | C13: 11000 | E13: =+C13 -> 11000 | H13: TOTALES | R13: =SUM(R4:R12) -> 215325 | S13: =SUM(S4:S12) -> 99307.86 | T13: =SUM(T4:T12) -> 419338.5
B14: TOTAL SUELDO | E14: =SUM(E4:E13) -> 110036.4 | R14: =+S13+T13+R13 -> 733971.36
B15: AGUINALDO PAGO | E15: 29825 | T15: =+T13-T4-T6-T11 -> 273275.7
B16: DEPOSITO | E16: 30000
B17: TOTAL A COBRAR | E17: =+E14-E15-E16 -> 50211.4 | R17: HORA | S17: HORA X | T17: NO REM.
Q18: JUANI | R18: =194*1.2 -> 232.8 | S18: =+R18*1.5 -> 349.2 | T18: 13500
B19: FACU | I19: DIAS | J19: HS | K19: DIC | Q19: JONA | R19: =180*1.2 -> 216 | S19: =+R19*1.5 -> 324 | T19: 13000
B20: DETALLE | C20: HS TRABAJADAS | D20: VALOR / HORA | E20: IMPORTE | H20: LABORAL | I20: 17 | J20: 9 | K20: =+I20*J20 -> 153 | Q20: FACU | R20: =180*1.2 -> 216 | S20: =+R20*1.5 -> 324 | T20: 13500
B21: SUELDO | C21: 181 | D21: 232.8 | E21: =C21*D21 -> 42136.8 | H21: FERIADO | I21: 1.5 | J21: 8 | K21: =+I21*J21 -> 12 | Q21: PILU | R21: =169.2*1.2 -> 203.04 | S21: =+R21*1.5 -> 304.56 | T21: 11000
B22: FERIADO | C22: 12 | D22: =+D21 -> 232.8 | E22: =+C22*D22 -> 2793.6 | H22: VIERNES | I22: 4 | J22: 8 | K22: =+I22*J22 -> 32 | Q22: CHACO | R22: =156*1.2 -> 187.2 | S22: =+R22*1.5 -> 280.8 | T22: 11000
B23: VACACIONES | I23: hs mes | K23: =SUM(K20:K22) -> 197 | Q23: LUCA | R23: 165 | S23: =+R23*1.5 -> 247.5 | T23: 8000
B24: AGUINALDO (Base: Dic) | E24: 38250 | Q24: ALEJO | R24: =132*1.2 -> 158.4 | S24: =+R24*1.5 -> 237.6 | T24: 8000
